Workbook

Sheet Resultados
A1: MUNICÍPIO | B1: IPARDES (43 creches) | C1: PCM (257 creches) | D1: TOTAL (300 creches)
A2: Curitiba | B2: 0 | C2: 10 | D2: =SUM(B2:C2) -> 10
A3: Londrina | B3: 0 | C3: 8 | D3: =SUM(B3:C3) -> 8
A4: Maringá | B4: 0 | C4: 6 | D4: =SUM(B4:C4) -> 6
A5: Ponta Grossa | B5: 0 | C5: 7 | D5: =SUM(B5:C5) -> 7
A6: Cascavel | B6: 0 | C6: 6 | D6: =SUM(B6:C6) -> 6
A7: São José dos Pinhais | B7: 0 | C7: 7 | D7: =SUM(B7:C7) -> 7
A8: Foz do Iguaçu | B8: 0 | C8: 6 | D8: =SUM(B8:C8) -> 6
A9: Colombo | B9: 0 | C9: 5 | D9: =SUM(B9:C9) -> 5
A10: Guarapuava | B10: 1 | C10: 3 | D10: =SUM(B10:C10) -> 4
A11: Araucária | B11: 0 | C11: 3 | D11: =SUM(B11:C11) -> 3
A12: Toledo | B12: 0 | C12: 2 | D12: =SUM(B12:C12) -> 2
A13: Fazenda Rio Grande | B13: 1 | C13: 3 | D13: =SUM(B13:C13) -> 4
... A93: Capanema | B93: 0 | C93: 0 | D93: =SUM(B93:C93) -> 0
A94: Tibagi | B94: 0 | C94: 1 | D94: 1
A95: Andirá | B95: 0 | C95: 0 | D95: 0
A96: Ampére | B96: 0 | C96: 0 | D96: =SUM(B96:C96) -> 0
A97: Realeza | B97: 0 | C97: 0 | D97: =SUM(B97:C97) -> 0
A98: Wenceslau Braz | B98: 1 | C98: 0 | D98: =SUM(B98:C98) -> 1
A99: Contenda | B99: 1 | C99: 0 | D99: =SUM(B99:C99) -> 1
A100: Cafelândia | B100: 0 | C100: 0 | D100: =SUM(B100:C100) -> 0
A101: Altônia | B101: 0 | C101: 0 | D101: =SUM(B101:C101) -> 0
A102: Matelândia | B102: 0 | C102: 0 | D102: =SUM(B102:C102) -> 0
A103: Quitandinha | B103: 0 | C103: 1 | D103: =SUM(B103:C103) -> 1
A104: Morretes | B104: 1 | C104: 0 | D104: =SUM(B104:C104) -> 1
A105: Terra Roxa | B105: 0 | C105: 0 | D105: =SUM(B105:C105) -> 0
A106: Antonina | B106: 0 | C106: 1 | D106: =SUM(B106:C106) -> 1
A107: Tijucas do Sul | B107: 1 | C107: 0 | D107: =SUM(B107:C107) -> 1
... A400: Nova Aliança do Ivaí | B400: 0 | C400: 0 | D400: =SUM(B400:C400) -> 0

Sheet Metodologia
A1: Classificação por Faixa | B1: Legenda de Cada Faixa | C1: População Alvo | D1: Proporção da População Alvo | E1: Número de Municípios | F1: Contemplado | G1: Prop Ajustado | H1: Ponderação Pop | I1: Total | J1: Proporção | K1: Limite de Creches Por Município | L1: Número de Municípios | M1: Distribuição por Faixa | N1: Método de Distribuição | O1: Proporção Final | Q1: Cobertura
A2: G2 | B2: Curitiba | C2: =SUMIF(Demográfico!M$2:M$400,Metodologia!A2,Demográfico!E$2:E$400) -> 202402 | D2: =C2/C$10 -> 0.13519027 | E2: =COUNTIF(Dados!C$2:C$400,Metodologia!A2) -> 1 | F2: Sim | G2: =IF(F2=P$2,SUMIF(Demográfico!M$2:M$400,Metodologia!A2,Demográfico!E$2:E$400),0) -> 202402 | H2: =IF(F2=P$2,D2*F$10,0) -> 23.114213 | I2: =SUMIF(Dados!C$2:C$400,Metodologia!A2,Dados!Q$2:Q$400) -> 30 | J2: =I2/F$11 -> 0.11673152 | K2: 10 | L2: 30 | M2: 10 | N2: Cálculo Proporção Populacional com o PCM | O2: =M2/M$10 -> 0.038910506 | P2: Sim | Q2: 1
A3: G1 | B3: Londrina | C3: =SUMIF(Demográfico!M$2:M$400,Metodologia!A3,Demográfico!E$2:E$400) -> 66820 | D3: =C3/C$10 -> 0.044631049 | E3: =COUNTIF(Dados!C$2:C$400,Metodologia!A3) -> 1 | F3: Sim | G3: =IF(F3=P$2,SUMIF(Demográfico!M$2:M$400,Metodologia!A3,Demográfico!E$2:E$400),0) -> 66820 | H3: =IF(F3=P$2,D3*F$10,0) -> 7.6308126 | I3: =SUMIF(Dados!C$2:C$400,Metodologia!A3,Dados!Q$2:Q$400) -> 11 | J3: =I3/F$11 -> 0.042801556 | K3: 8 | M3: 90 | O3: =M3/M$10 -> 0.35019455 | P3: Não
A4: M2 | B4: Entre 200 até 500 mil habitantes | C4: =SUMIF(Demográfico!M$2:M$400,Metodologia!A4,Demográfico!E$2:E$400) -> 261249 | D4: =C4/C$10 -> 0.17449591 | E4: =COUNTIF(Dados!C$2:C$400,Metodologia!A4) -> 6 | F4: Sim | G4: =IF(F4=P$2,SUMIF(Demográfico!M$2:M$400,Metodologia!A4,Demográfico!E$2:E$400),0) -> 261249 | H4: =IF(F4=P$2,D4*F$10,0) -> 29.834513 | I4: =SUMIF(Dados!C$2:C$400,Metodologia!A4,Dados!Q$2:Q$400) -> 44 | J4: =I4/F$11 -> 0.17120623 | K4: 7
A5: M1 | B5: Entre 100 até 200 mil habitantes | C5: =SUMIF(Demográfico!M$2:M$400,Metodologia!A5,Demográfico!E$2:E$400) -> 263104 | D5: =C5/C$10 -> 0.17573492 | E5: =COUNTIF(Dados!C$2:C$400,Metodologia!A5) -> 14 | F5: Sim | G5: =IF(F5=P$2,SUMIF(Demográfico!M$2:M$400,Metodologia!A5,Demográfico!E$2:E$400),0) -> 263104 | H5: =IF(F5=P$2,D5*F$10,0) -> 30.046353 | I5: =SUMIF(Dados!C$2:C$400,Metodologia!A5,Dados!Q$2:Q$400) -> 41 | J5: =I5/F$11 -> 0.15953307 | K5: 4
A6: P4 | B6: Entre 70 a 100 mil habitantes | C6: =SUMIF(Demográfico!M$2:M$400,Metodologia!A6,Demográfico!E$2:E$400) -> 90999 | D6: =C6/C$10 -> 0.060780916 | E6: =COUNTIF(Dados!C$2:C$400,Metodologia!A6) -> 8 | F6: Sim | G6: =IF(F6=P$2,SUMIF(Demográfico!M$2:M$400,Metodologia!A6,Demográfico!E$2:E$400),0) -> 90999 | H6: =IF(F6=P$2,D6*F$10,0) -> 10.392043 | I6: =SUMIF(Dados!C$2:C$400,Metodologia!A6,Dados!Q$2:Q$400) -> 16 | J6: =I6/F$11 -> 0.062256809 | K6: 2 | P6: =SUM(G2:G9) -> 1497164
A7: P3 | B7: Entre 20 a 70 mil habitantes | C7: =SUMIF(Demográfico!M$2:M$400,Metodologia!A7,Demográfico!E$2:E$400) -> 280446 | D7: =C7/C$10 -> 0.18731816 | E7: =COUNTIF(Dados!C$2:C$400,Metodologia!A7) -> 62 | F7: Sim | G7: =IF(F7=P$2,SUMIF(Demográfico!M$2:M$400,Metodologia!A7,Demográfico!E$2:E$400),0) -> 280446 | H7: =IF(F7=P$2,D7*F$10,0) -> 32.026801 | I7: =SUMIF(Dados!C$2:C$400,Metodologia!A7,Dados!Q$2:Q$400) -> 57 | J7: =I7/F$11 -> 0.22178988 | K7: 1 | L7: 62 | M7: 27 | N7: Ranking do PCM (Com maior peso no fator socioeconômico) | O7: =M7/M$10 -> 0.10505837 | Q7: =M7/L7 -> 0.43548387
A8: P2 | B8: Entre 5 a 20 mil habitantes | C8: =SUMIF(Demográfico!M$2:M$400,Metodologia!A8,Demográfico!E$2:E$400) -> 285766 | D8: =C8/C$10 -> 0.19087154 | E8: =COUNTIF(Dados!C$2:C$400,Metodologia!A8) -> 205 | F8: Sim | G8: =IF(F8=P$2,SUMIF(Demográfico!M$2:M$400,Metodologia!A8,Demográfico!E$2:E$400),0) -> 285766 | H8: =IF(F8=P$2,D8*F$10,0) -> 32.634343 | I8: =SUMIF(Dados!C$2:C$400,Metodologia!A8,Dados!Q$2:Q$400) -> 5 | J8: =I8/F$11 -> 0.019455253 | K8: 1 | L8: 205 | M8: 100 | O8: =M8/M$10 -> 0.38910506 | Q8: =M8/L8 -> 0.48780488
A9: P1 | B9: Até 5 mil habitantes | C9: =SUMIF(Demográfico!M$2:M$400,Metodologia!A9,Demográfico!E$2:E$400) -> 46378 | D9: =C9/C$10 -> 0.030977234 | E9: =COUNTIF(Dados!C$2:C$400,Metodologia!A9) -> 102 | F9: Sim | G9: =IF(F9=P$2,SUMIF(Demográfico!M$2:M$400,Metodologia!A9,Demográfico!E$2:E$400),0) -> 46378 | H9: =IF(F9=P$2,D9*F$10,0) -> 5.2963458 | I9: =SUMIF(Dados!C$2:C$400,Metodologia!A9,Dados!Q$2:Q$400) -> -3 | J9: =I9/F$11 -> -0.011673152 | K9: 1 | L9: 102 | M9: 30 | O9: =M9/M$10 -> 0.11673152 | Q9: =M9/L9 -> 0.29411765
A10: TOTAL | C10: =SUM(G2:G9) -> 1497164 | E10: SIMULAÇÃO | F10: =F11/(1+C11) -> 170.97542 | L10: =SUM(L2:L9) -> 399 | M10: =SUM(M2:M9) -> 257
A11: PCM Ponderado | C11: =0.50314 -> 0.50314 | D11: Creches | F11: 257

Sheet Dados
A1: MUNICÍPIO | B1: POPULAÇÃO | C1: PORTE DO MUNICÍPIO | D1: CALCULO PROPORÇÃO | E1: FATOR EDUCAÇÃO | F1: FATOR DEMOGRÁFICO | G1: FATOR SOCIOECONÔMICO | H1: PCM | I1: IPARDES | J1: PROPORÇÃO CRECHES | K1: APROX. CRECHES | P1: =SUM(K$2:K$400)-(SUM(N$2:N$400)) -> 111.43674 | Q1: TOTAL CRECHES
A2: Curitiba | B2: 1773718 | C2: {=_xlfn.IFS(B2<5000, "P1",B2<20000, "P2",B2<70000, "P3",B2<100000, "P4",B2<200000,"M1",B2<500000,"M2",B2<1000000,"G1",B2>1000000,"G2")} -> G2 | D2: =VLOOKUP(C2,Metodologia!A$2:H$9,8,FALSE) -> 23.114213 | E2: =VLOOKUP(A2,Educacional!A$2:P$405,16,FALSE) -> 56.511036 | F2: =VLOOKUP(A2,Demográfico!A$2:L$405,12,FALSE) -> 29.902254 | G2: =VLOOKUP(A2,Socioeconômico!A$2:M$405,13,FALSE) -> 0 | H2: =(2*E2+F2+2*G2)/5/100 -> 0.28584865 | I2: =VLOOKUP(A2,Resultados!A$2:B400,2,FALSE) -> 0 | J2: =IFERROR(VLOOKUP(A2,Demográfico!A$2:E$400,5,FALSE)/(VLOOKUP(C2,Metodologia!A$2:G$9,7,FALSE))*D2,0) -> 23.114213 | K2: =(J2*(1+H2)-I2) -> 29.72138 | L2: =INT(K2) -> 29 | M2: =VLOOKUP(A2,Demográfico!A$2:E$400,5,FALSE)*H2 -> 57856.339 | N2: =FLOOR(K2,1) -> 29 | O2: =K2-N2 -> 0.72137993 | P2: =IFERROR(RANK(O2,O$2:O$400,0),0) -> 29 | Q2: =N2+IF(P2<P$1,1,0) -> 30 | S2: =VLOOKUP(A2,Demográfico!A$2:E$400,5,FALSE)*(H2) -> 57856.339 | T2: =IFERROR(D2/D2,0) -> 1 | U2: =S2*T2 -> 57856.339
A3: Londrina | B3: 555965 | C3: {=_xlfn.IFS(B3<5000, "P1",B3<20000, "P2",B3<70000, "P3",B3<100000, "P4",B3<200000,"M1",B3<500000,"M2",B3<1000000,"G1",B3>1000000,"G2")} -> G1 | D3: =VLOOKUP(C3,Metodologia!A$2:H$9,8,FALSE) -> 7.6308126 | E3: =VLOOKUP(A3,Educacional!A$2:P$405,16,FALSE) -> 65.89371 | F3: =VLOOKUP(A3,Demográfico!A$2:L$405,12,FALSE) -> 39.540641 | G3: =VLOOKUP(A3,Socioeconômico!A$2:M$405,13,FALSE) -> 24.244683 | H3: =(2*E3+F3+2*G3)/5/100 -> 0.43963486 | I3: =VLOOKUP(A3,Resultados!A$2:B401,2,FALSE) -> 0 | J3: =IFERROR(VLOOKUP(A3,Demográfico!A$2:E$400,5,FALSE)/(VLOOKUP(C3,Metodologia!A$2:G$9,7,FALSE))*D3,0) -> 7.6308126 | K3: =(J3*(1+H3)-I3) -> 10.985584 | L3: 4 | M3: =VLOOKUP(A3,Demográfico!A$2:E$400,5,FALSE)*H3 -> 29376.401 | N3: =FLOOR(K3,1) -> 10 | O3: =K3-N3 -> 0.98558378 | P3: =IFERROR(RANK(O3,O$2:O$400,0),0) -> 3 | Q3: =N3+IF(P3<P$1,1,0) -> 11 | S3: =VLOOKUP(A3,Demográfico!A$2:E$400,5,FALSE)*(H3) -> 29376.401 | T3: =IFERROR(D3/D3,0) -> 1 | U3: =S3*T3 -> 29376.401
A4: Maringá | B4: 409657 | C4: {=_xlfn.IFS(B4<5000, "P1",B4<20000, "P2",B4<70000, "P3",B4<100000, "P4",B4<200000,"M1",B4<500000,"M2",B4<1000000,"G1",B4>1000000,"G2")} -> M2 | D4: =VLOOKUP(C4,Metodologia!A$2:H$9,8,FALSE) -> 29.834513 | E4: =VLOOKUP(A4,Educacional!A$2:P$405,16,FALSE) -> 48.551508 | F4: =VLOOKUP(A4,Demográfico!A$2:L$405,12,FALSE) -> 32.36445 | G4: =VLOOKUP(A4,Socioeconômico!A$2:M$405,13,FALSE) -> 12.678385 | H4: =(2*E4+F4+2*G4)/5/100 -> 0.30964847 | I4: =VLOOKUP(A4,Resultados!A$2:B402,2,FALSE) -> 0 | J4: =IFERROR(VLOOKUP(A4,Demográfico!A$2:E$400,5,FALSE)/(VLOOKUP(C4,Metodologia!A$2:G$9,7,FALSE))*D4,0) -> 5.2013318 | K4: =(J4*(1+H4)-I4) -> 6.8119162 | L4: 3 | M4: =VLOOKUP(A4,Demográfico!A$2:E$400,5,FALSE)*H4 -> 14103.249 | N4: =FLOOR(K4,1) -> 6 | O4: =K4-N4 -> 0.81191621 | P4: =IFERROR(RANK(O4,O$2:O$400,0),0) -> 21 | Q4: =N4+IF(P4<P$1,1,0) -> 7 | S4: =VLOOKUP(A4,Demográfico!A$2:E$400,5,FALSE)*(H4) -> 14103.249 | T4: =IFERROR(D4/D4,0) -> 1 | U4: =S4*T4 -> 14103.249
A5: Ponta Grossa | B5: 358371 | C5: {=_xlfn.IFS(B5<5000, "P1",B5<20000, "P2",B5<70000, "P3",B5<100000, "P4",B5<200000,"M1",B5<500000,"M2",B5<1000000,"G1",B5>1000000,"G2")} -> M2 | D5: =VLOOKUP(C5,Metodologia!A$2:H$9,8,FALSE) -> 29.834513 | E5: =VLOOKUP(A5,Educacional!A$2:P$405,16,FALSE) -> 70.225565 | F5: =VLOOKUP(A5,Demográfico!A$2:L$405,12,FALSE) -> 50.638697 | G5: =VLOOKUP(A5,Socioeconômico!A$2:M$405,13,FALSE) -> 23.835003 | H5: =(2*E5+F5+2*G5)/5/100 -> 0.47751966 | I5: =VLOOKUP(A5,Resultados!A$2:B403,2,FALSE) -> 0 | J5: =IFERROR(VLOOKUP(A5,Demográfico!A$2:E$400,5,FALSE)/(VLOOKUP(C5,Metodologia!A$2:G$9,7,FALSE))*D5,0) -> 5.7618231 | K5: =(J5*(1+H5)-I5) -> 8.5132069 | L5: 3 | M5: =VLOOKUP(A5,Demográfico!A$2:E$400,5,FALSE)*H5 -> 24092.777 | N5: =FLOOR(K5,1) -> 8 | O5: =K5-N5 -> 0.5132069 | P5: =IFERROR(RANK(O5,O$2:O$400,0),0) -> 63 | Q5: =N5+IF(P5<P$1,1,0) -> 9 | S5: =VLOOKUP(A5,Demográfico!A$2:E$400,5,FALSE)*(H5) -> 24092.777 | T5: =IFERROR(D5/D5,0) -> 1 | U5: =S5*T5 -> 24092.777
A6: Cascavel | B6: 348051 | C6: {=_xlfn.IFS(B6<5000, "P1",B6<20000, "P2",B6<70000, "P3",B6<100000, "P4",B6<200000,"M1",B6<500000,"M2",B6<1000000,"G1",B6>1000000,"G2")} -> M2 | D6: =VLOOKUP(C6,Metodologia!A$2:H$9,8,FALSE) -> 29.834513 | E6: =VLOOKUP(A6,Educacional!A$2:P$405,16,FALSE) -> 62.192264 | F6: =VLOOKUP(A6,Demográfico!A$2:L$405,12,FALSE) -> 46.363931 | G6: =VLOOKUP(A6,Socioeconômico!A$2:M$405,13,FALSE) -> 12.08241 | H6: =(2*E6+F6+2*G6)/5/100 -> 0.38982656 | I6: =VLOOKUP(A6,Resultados!A$2:B404,2,FALSE) -> 0 | J6: =IFERROR(VLOOKUP(A6,Demográfico!A$2:E$400,5,FALSE)/(VLOOKUP(C6,Metodologia!A$2:G$9,7,FALSE))*D6,0) -> 5.1526828 | K6: =(J6*(1+H6)-I6) -> 7.1613354 | L6: 3 | M6: =VLOOKUP(A6,Demográfico!A$2:E$400,5,FALSE)*H6 -> 17588.974 | N6: =FLOOR(K6,1) -> 7 | O6: =K6-N6 -> 0.16133537 | P6: =IFERROR(RANK(O6,O$2:O$400,0),0) -> 230 | Q6: =N6+IF(P6<P$1,1,0) -> 7 | S6: =VLOOKUP(A6,Demográfico!A$2:E$400,5,FALSE)*(H6) -> 17588.974 | T6: =IFERROR(D6/D6,0) -> 1 | U6: =S6*T6 -> 17588.974
A7: São José dos Pinhais | B7: 329628 | C7: {=_xlfn.IFS(B7<5000, "P1",B7<20000, "P2",B7<70000, "P3",B7<100000, "P4",B7<200000,"M1",B7<500000,"M2",B7<1000000,"G1",B7>1000000,"G2")} -> M2 | D7: =VLOOKUP(C7,Metodologia!A$2:H$9,8,FALSE) -> 29.834513 | E7: =VLOOKUP(A7,Educacional!A$2:P$405,16,FALSE) -> 71.120463 | F7: =VLOOKUP(A7,Demográfico!A$2:L$405,12,FALSE) -> 51.131176 | G7: =VLOOKUP(A7,Socioeconômico!A$2:M$405,13,FALSE) -> 14.61558 | H7: =(2*E7+F7+2*G7)/5/100 -> 0.44520652 | I7: =VLOOKUP(A7,Resultados!A$2:B405,2,FALSE) -> 0 | J7: =IFERROR(VLOOKUP(A7,Demográfico!A$2:E$400,5,FALSE)/(VLOOKUP(C7,Metodologia!A$2:G$9,7,FALSE))*D7,0) -> 5.3692051 | K7: =(J7*(1+H7)-I7) -> 7.7596102 | L7: 3 | M7: =VLOOKUP(A7,Demográfico!A$2:E$400,5,FALSE)*H7 -> 20931.83 | N7: =FLOOR(K7,1) -> 7 | O7: =K7-N7 -> 0.75961023 | P7: =IFERROR(RANK(O7,O$2:O$400,0),0) -> 25 | Q7: =N7+IF(P7<P$1,1,0) -> 8 | S7: =VLOOKUP(A7,Demográfico!A$2:E$400,5,FALSE)*(H7) -> 20931.83 | T7: =IFERROR(D7/D7,0) -> 1 | U7: =S7*T7 -> 20931.83
A8: Foz do Iguaçu | B8: 285415 | C8: {=_xlfn.IFS(B8<5000, "P1",B8<20000, "P2",B8<70000, "P3",B8<100000, "P4",B8<200000,"M1",B8<500000,"M2",B8<1000000,"G1",B8>1000000,"G2")} -> M2 | D8: =VLOOKUP(C8,Metodologia!A$2:H$9,8,FALSE) -> 29.834513 | E8: =VLOOKUP(A8,Educacional!A$2:P$405,16,FALSE) -> 59.854018 | F8: =VLOOKUP(A8,Demográfico!A$2:L$405,12,FALSE) -> 53.393821 | G8: =VLOOKUP(A8,Socioeconômico!A$2:M$405,13,FALSE) -> 30.757393 | H8: =(2*E8+F8+2*G8)/5/100 -> 0.46923329 | I8: =VLOOKUP(A8,Resultados!A$2:B406,2,FALSE) -> 0 | J8: =IFERROR(VLOOKUP(A8,Demográfico!A$2:E$400,5,FALSE)/(VLOOKUP(C8,Metodologia!A$2:G$9,7,FALSE))*D8,0) -> 4.5087116 | K8: =(J8*(1+H8)-I8) -> 6.6243492 | L8: 3 | M8: =VLOOKUP(A8,Demográfico!A$2:E$400,5,FALSE)*H8 -> 18525.799 | N8: =FLOOR(K8,1) -> 6 | O8: =K8-N8 -> 0.62434922 | P8: =IFERROR(RANK(O8,O$2:O$400,0),0) -> 43 | Q8: =N8+IF(P8<P$1,1,0) -> 7 | S8: =VLOOKUP(A8,Demográfico!A$2:E$400,5,FALSE)*(H8) -> 18525.799 | T8: =IFERROR(D8/D8,0) -> 1 | U8: =S8*T8 -> 18525.799
A9: Colombo | B9: 232212 | C9: {=_xlfn.IFS(B9<5000, "P1",B9<20000, "P2",B9<70000, "P3",B9<100000, "P4",B9<200000,"M1",B9<500000,"M2",B9<1000000,"G1",B9>1000000,"G2")} -> M2 | D9: =VLOOKUP(C9,Metodologia!A$2:H$9,8,FALSE) -> 29.834513 | E9: =VLOOKUP(A9,Educacional!A$2:P$405,16,FALSE) -> 66.409354 | F9: =VLOOKUP(A9,Demográfico!A$2:L$405,12,FALSE) -> 50.192481 | G9: =VLOOKUP(A9,Socioeconômico!A$2:M$405,13,FALSE) -> 37.235331 | H9: =(2*E9+F9+2*G9)/5/100 -> 0.5149637 | I9: =VLOOKUP(A9,Resultados!A$2:B407,2,FALSE) -> 0 | J9: =IFERROR(VLOOKUP(A9,Demográfico!A$2:E$400,5,FALSE)/(VLOOKUP(C9,Metodologia!A$2:G$9,7,FALSE))*D9,0) -> 3.8407586 | K9: =(J9*(1+H9)-I9) -> 5.8186098 | L9: 2 | M9: =VLOOKUP(A9,Demográfico!A$2:E$400,5,FALSE)*H9 -> 17319.259 | N9: =FLOOR(K9,1) -> 5 | O9: =K9-N9 -> 0.81860984 | P9: =IFERROR(RANK(O9,O$2:O$400,0),0) -> 20 | Q9: =N9+IF(P9<P$1,1,0) -> 6 | S9: =VLOOKUP(A9,Demográfico!A$2:E$400,5,FALSE)*(H9) -> 17319.259 | T9: =IFERROR(D9/D9,0) -> 1 | U9: =S9*T9 -> 17319.259
A10: Guarapuava | B10: 182093 | C10: {=_xlfn.IFS(B10<5000, "P1",B10<20000, "P2",B10<70000, "P3",B10<100000, "P4",B10<200000,"M1",B10<500000,"M2",B10<1000000,"G1",B10>1000000,"G2")} -> M1 | D10: =VLOOKUP(C10,Metodologia!A$2:H$9,8,FALSE) -> 30.046353 | E10: =VLOOKUP(A10,Educacional!A$2:P$405,16,FALSE) -> 61.083403 | F10: =VLOOKUP(A10,Demográfico!A$2:L$405,12,FALSE) -> 55.600277 | G10: =VLOOKUP(A10,Socioeconômico!A$2:M$405,13,FALSE) -> 28.384009 | H10: =(2*E10+F10+2*G10)/5/100 -> 0.4690702 | I10: =VLOOKUP(A10,Resultados!A$2:B408,2,FALSE) -> 1 | J10: =IFERROR(VLOOKUP(A10,Demográfico!A$2:E$400,5,FALSE)/(VLOOKUP(C10,Metodologia!A$2:G$9,7,FALSE))*D10,0) -> 2.9182548 | K10: =(J10*(1+H10)-I10) -> 3.2871212 | L10: 2 | M10: =VLOOKUP(A10,Demográfico!A$2:E$400,5,FALSE)*H10 -> 11986.62 | N10: =FLOOR(K10,1) -> 3 | O10: =K10-N10 -> 0.28712115 | P10: =IFERROR(RANK(O10,O$2:O$400,0),0) -> 144 | Q10: =N10+IF(P10<P$1,1,0) -> 3 | S10: =VLOOKUP(A10,Demográfico!A$2:E$400,5,FALSE)*(H10) -> 11986.62 | T10: =IFERROR(D10/D10,0) -> 1 | U10: =S10*T10 -> 11986.62
A11: Araucária | B11: 151666 | C11: {=_xlfn.IFS(B11<5000, "P1",B11<20000, "P2",B11<70000, "P3",B11<100000, "P4",B11<200000,"M1",B11<500000,"M2",B11<1000000,"G1",B11>1000000,"G2")} -> M1 | D11: =VLOOKUP(C11,Metodologia!A$2:H$9,8,FALSE) -> 30.046353 | E11: =VLOOKUP(A11,Educacional!A$2:P$405,16,FALSE) -> 48.892273 | F11: =VLOOKUP(A11,Demográfico!A$2:L$405,12,FALSE) -> 49.468609 | G11: =VLOOKUP(A11,Socioeconômico!A$2:M$405,13,FALSE) -> 16.192753 | H11: =(2*E11+F11+2*G11)/5/100 -> 0.35927732 | I11: =VLOOKUP(A11,Resultados!A$2:B409,2,FALSE) -> 0 | J11: =IFERROR(VLOOKUP(A11,Demográfico!A$2:E$400,5,FALSE)/(VLOOKUP(C11,Metodologia!A$2:G$9,7,FALSE))*D11,0) -> 2.5503039 | K11: =(J11*(1+H11)-I11) -> 3.4665703 | L11: 2 | M11: =VLOOKUP(A11,Demográfico!A$2:E$400,5,FALSE)*H11 -> 8023.3812 | N11: =FLOOR(K11,1) -> 3 | O11: =K11-N11 -> 0.46657026 | P11: =IFERROR(RANK(O11,O$2:O$400,0),0) -> 71 | Q11: =N11+IF(P11<P$1,1,0) -> 4 | S11: =VLOOKUP(A11,Demográfico!A$2:E$400,5,FALSE)*(H11) -> 8023.3812 | T11: =IFERROR(D11/D11,0) -> 1 | U11: =S11*T11 -> 8023.3812
A12: Toledo | B12: 150470 | C12: {=_xlfn.IFS(B12<5000, "P1",B12<20000, "P2",B12<70000, "P3",B12<100000, "P4",B12<200000,"M1",B12<500000,"M2",B12<1000000,"G1",B12>1000000,"G2")} -> M1 | D12: =VLOOKUP(C12,Metodologia!A$2:H$9,8,FALSE) -> 30.046353 | E12: =VLOOKUP(A12,Educacional!A$2:P$405,16,FALSE) -> 51.77083 | F12: =VLOOKUP(A12,Demográfico!A$2:L$405,12,FALSE) -> 46.319074 | G12: =VLOOKUP(A12,Socioeconômico!A$2:M$405,13,FALSE) -> 7.3073309 | H12: =(2*E12+F12+2*G12)/5/100 -> 0.32895079 | I12: =VLOOKUP(A12,Resultados!A$2:B410,2,FALSE) -> 0 | J12: =IFERROR(VLOOKUP(A12,Demográfico!A$2:E$400,5,FALSE)/(VLOOKUP(C12,Metodologia!A$2:G$9,7,FALSE))*D12,0) -> 2.2337428 | K12: =(J12*(1+H12)-I12) -> 2.9685343 | L12: 2 | M12: =VLOOKUP(A12,Demográfico!A$2:E$400,5,FALSE)*H12 -> 6434.2775 | N12: =FLOOR(K12,1) -> 2 | O12: =K12-N12 -> 0.96853427 | P12: =IFERROR(RANK(O12,O$2:O$400,0),0) -> 6 | Q12: =N12+IF(P12<P$1,1,0) -> 3 | S12: =VLOOKUP(A12,Demográfico!A$2:E$400,5,FALSE)*(H12) -> 6434.2775 | T12: =IFERROR(D12/D12,0) -> 1 | U12: =S12*T12 -> 6434.2775
A13: Fazenda Rio Grande | B13: 148873 | C13: {=_xlfn.IFS(B13<5000, "P1",B13<20000, "P2",B13<70000, "P3",B13<100000, "P4",B13<200000,"M1",B13<500000,"M2",B13<1000000,"G1",B13>1000000,"G2")} -> M1 | D13: =VLOOKUP(C13,Metodologia!A$2:H$9,8,FALSE) -> 30.046353 | E13: =VLOOKUP(A13,Educacional!A$2:P$405,16,FALSE) -> 76.705674 | F13: =VLOOKUP(A13,Demográfico!A$2:L$405,12,FALSE) -> 60.165164 | G13: =VLOOKUP(A13,Socioeconômico!A$2:M$405,13,FALSE) -> 27.811608 | H13: =(2*E13+F13+2*G13)/5/100 -> 0.53839946 | I13: =VLOOKUP(A13,Resultados!A$2:B411,2,FALSE) -> 1 | J13: =IFERROR(VLOOKUP(A13,Demográfico!A$2:E$400,5,FALSE)/(VLOOKUP(C13,Metodologia!A$2:G$9,7,FALSE))*D13,0) -> 2.811364 | K13: =(J13*(1+H13)-I13) -> 3.3250009 | L13: 2 | M13: =VLOOKUP(A13,Demográfico!A$2:E$400,5,FALSE)*H13 -> 13254.318 | N13: =FLOOR(K13,1) -> 3 | O13: =K13-N13 -> 0.32500089 | P13: =IFERROR(RANK(O13,O$2:O$400,0),0) -> 128 | Q13: =N13+IF(P13<P$1,1,0) -> 3 | S13: =VLOOKUP(A13,Demográfico!A$2:E$400,5,FALSE)*(H13) -> 13254.318 | T13: =IFERROR(D13/D13,0) -> 1 | U13: =S13*T13 -> 13254.318
A14: Paranaguá | B14: 145829 | C14: {=_xlfn.IFS(B14<5000, "P1",B14<20000, "P2",B14<70000, "P3",B14<100000, "P4",B14<200000,"M1",B14<500000,"M2",B14<1000000,"G1",B14>1000000,"G2")} -> M1 | D14: =VLOOKUP(C14,Metodologia!A$2:H$9,8,FALSE) -> 30.046353 | E14: =VLOOKUP(A14,Educacional!A$2:P$405,16,FALSE) -> 65.086632 | F14: =VLOOKUP(A14,Demográfico!A$2:L$405,12,FALSE) -> 57.47484 | G14: =VLOOKUP(A14,Socioeconômico!A$2:M$405,13,FALSE) -> 27.509811 | H14: =(2*E14+F14+2*G14)/5/100 -> 0.48533545 | I14: =VLOOKUP(A14,Resultados!A$2:B412,2,FALSE) -> 1 | J14: =IFERROR(VLOOKUP(A14,Demográfico!A$2:E$400,5,FALSE)/(VLOOKUP(C14,Metodologia!A$2:G$9,7,FALSE))*D14,0) -> 2.4064125 | K14: =(J14*(1+H14)-I14) -> 2.5743298 | L14: 2 | M14: =VLOOKUP(A14,Demográfico!A$2:E$400,5,FALSE)*H14 -> 10226.989 | N14: =FLOOR(K14,1) -> 2 | O14: =K14-N14 -> 0.57432979 | P14: =IFERROR(RANK(O14,O$2:O$400,0),0) -> 54 | Q14: =N14+IF(P14<P$1,1,0) -> 3 | S14: =VLOOKUP(A14,Demográfico!A$2:E$400,5,FALSE)*(H14) -> 10226.989 | T14: =IFERROR(D14/D14,0) -> 1 | U14: =S14*T14 -> 10226.989
... A31: Rolândia | B31: 71670 | C31: {=_xlfn.IFS(B31<5000, "P1",B31<20000, "P2",B31<70000, "P3",B31<100000, "P4",B31<200000,"M1",B31<500000,"M2",B31<1000000,"G1",B31>1000000,"G2")} -> P4 | D31: =VLOOKUP(C31,Metodologia!A$2:H$9,8,FALSE) -> 10.392043 | E31: =VLOOKUP(A31,Educacional!A$2:P$405,16,FALSE) -> 61.898387 | F31: =VLOOKUP(A31,Demográfico!A$2:L$405,12,FALSE) -> 51.665505 | G31: =VLOOKUP(A31,Socioeconômico!A$2:M$405,13,FALSE) -> 20.824024 | H31: =(2*E31+F31+2*G31)/5/100 -> 0.43422066 | I31: =VLOOKUP(A31,Resultados!A$2:B429,2,FALSE) -> 0 | J31: =IFERROR(VLOOKUP(A31,Demográfico!A$2:E$400,5,FALSE)/(VLOOKUP(C31,Metodologia!A$2:G$9,7,FALSE))*D31,0) -> 1.0858091 | K31: =(J31*(1+H31)-I31) -> 1.5572899 | L31: 1 | M31: =VLOOKUP(A31,Demográfico!A$2:E$400,5,FALSE)*H31 -> 4128.57 | N31: =FLOOR(K31,1) -> 1 | O31: =K31-N31 -> 0.55728988 | P31: =IFERROR(RANK(O31,O$2:O$400,0),0) -> 56 | Q31: =N31+IF(P31<P$1,1,0) -> 2 | S31: =VLOOKUP(A31,Demográfico!A$2:E$400,5,FALSE)*(H31) -> 4128.57 | T31: =IFERROR(D31/D31,0) -> 1 | U31: =S31*T31 -> 4128.57
A32: Irati | B32: 59250 | C32: {=_xlfn.IFS(B32<5000, "P1",B32<20000, "P2",B32<70000, "P3",B32<100000, "P4",B32<200000,"M1",B32<500000,"M2",B32<1000000,"G1",B32>1000000,"G2")} -> P3 | D32: =VLOOKUP(C32,Metodologia!A$2:H$9,8,FALSE) -> 32.026801 | E32: =VLOOKUP(A32,Educacional!A$2:P$405,16,FALSE) -> 65.322946 | F32: =VLOOKUP(A32,Demográfico!A$2:L$405,12,FALSE) -> 42.090227 | G32: =VLOOKUP(A32,Socioeconômico!A$2:M$405,13,FALSE) -> 40.366403 | H32: =(1*E32+F32+3*G32)/5/100 -> 0.45702477 | I32: =VLOOKUP(A32,Resultados!A$2:B430,2,FALSE) -> 0 | J32: =IFERROR(VLOOKUP(A32,Demográfico!A$2:E$400,5,FALSE)/(VLOOKUP(C32,Metodologia!A$2:G$9,7,FALSE))*D32,0) -> 0.87613879 | K32: =(J32*(1+H32)-I32) -> 1.2765559 | L32: 1 | M32: =VLOOKUP(A32,Demográfico!A$2:E$400,5,FALSE)*H32 -> 3506.294 | N32: =IFERROR(FLOOR(K32,1),0) -> 1 | O32: =K32-N32 -> 0.27655592 | P32: =IFERROR(RANK(O32,O$2:O$400,0),0) -> 149 | Q32: =N32+IF(P32<P$1,1,0) -> 1 | S32: =VLOOKUP(A32,Demográfico!A$2:E$400,5,FALSE)*(H32) -> 3506.294 | T32: =IFERROR(D32/D32,0) -> 1 | U32: =S32*T32 -> 3506.294
A33: Marechal Cândido Rondon | B33: 55836 | C33: {=_xlfn.IFS(B33<5000, "P1",B33<20000, "P2",B33<70000, "P3",B33<100000, "P4",B33<200000,"M1",B33<500000,"M2",B33<1000000,"G1",B33>1000000,"G2")} -> P3 | D33: =VLOOKUP(C33,Metodologia!A$2:H$9,8,FALSE) -> 32.026801 | E33: =VLOOKUP(A33,Educacional!A$2:P$405,16,FALSE) -> 48.26524 | F33: =VLOOKUP(A33,Demográfico!A$2:L$405,12,FALSE) -> 43.874612 | G33: =VLOOKUP(A33,Socioeconômico!A$2:M$405,13,FALSE) -> 13.962973 | H33: =(1*E33+F33+3*G33)/5/100 -> 0.26805754 | I33: =VLOOKUP(A33,Resultados!A$2:B431,2,FALSE) -> 0 | J33: =IFERROR(VLOOKUP(A33,Demográfico!A$2:E$400,5,FALSE)/(VLOOKUP(C33,Metodologia!A$2:G$9,7,FALSE))*D33,0) -> 0.79311573 | K33: =(J33*(1+H33)-I33) -> 1.0057164 | L33: 1 | M33: =VLOOKUP(A33,Demográfico!A$2:E$400,5,FALSE)*H33 -> 1861.6596 | N33: =IFERROR(FLOOR(K33,1),0) -> 1 | O33: =K33-N33 -> 0.005716386 | P33: =IFERROR(RANK(O33,O$2:O$400,0),0) -> 399 | Q33: =N33+IF(P33<P$1,1,0) -> 1 | S33: =VLOOKUP(A33,Demográfico!A$2:E$400,5,FALSE)*(H33) -> 1861.6596 | T33: =IFERROR(D33/D33,0) -> 1 | U33: =S33*T33 -> 1861.6596
A34: União da Vitória | B34: 55033 | C34: {=_xlfn.IFS(B34<5000, "P1",B34<20000, "P2",B34<70000, "P3",B34<100000, "P4",B34<200000,"M1",B34<500000,"M2",B34<1000000,"G1",B34>1000000,"G2")} -> P3 | D34: =VLOOKUP(C34,Metodologia!A$2:H$9,8,FALSE) -> 32.026801 | E34: =VLOOKUP(A34,Educacional!A$2:P$405,16,FALSE) -> 55.995839 | F34: =VLOOKUP(A34,Demográfico!A$2:L$405,12,FALSE) -> 46.190755 | G34: =VLOOKUP(A34,Socioeconômico!A$2:M$405,13,FALSE) -> 32.95685 | H34: =(1*E34+F34+3*G34)/5/100 -> 0.40211429 | I34: =VLOOKUP(A34,Resultados!A$2:B432,2,FALSE) -> 0 | J34: =IFERROR(VLOOKUP(A34,Demográfico!A$2:E$400,5,FALSE)/(VLOOKUP(C34,Metodologia!A$2:G$9,7,FALSE))*D34,0) -> 0.82303601 | K34: =(J34*(1+H34)-I34) -> 1.1539906 | L34: 1 | M34: =VLOOKUP(A34,Demográfico!A$2:E$400,5,FALSE)*H34 -> 2898.0377 | N34: =IFERROR(FLOOR(K34,1),0) -> 1 | O34: =K34-N34 -> 0.15399055 | P34: =IFERROR(RANK(O34,O$2:O$400,0),0) -> 240 | Q34: =N34+IF(P34<P$1,1,0) -> 1 | S34: =VLOOKUP(A34,Demográfico!A$2:E$400,5,FALSE)*(H34) -> 2898.0377 | T34: =IFERROR(D34/D34,0) -> 1 | U34: =S34*T34 -> 2898.0377
A35: Medianeira | B35: 54369 | C35: {=_xlfn.IFS(B35<5000, "P1",B35<20000, "P2",B35<70000, "P3",B35<100000, "P4",B35<200000,"M1",B35<500000,"M2",B35<1000000,"G1",B35>1000000,"G2")} -> P3 | D35: =VLOOKUP(C35,Metodologia!A$2:H$9,8,FALSE) -> 32.026801 | E35: =VLOOKUP(A35,Educacional!A$2:P$405,16,FALSE) -> 44.364029 | F35: =VLOOKUP(A35,Demográfico!A$2:L$405,12,FALSE) -> 54.951014 | G35: =VLOOKUP(A35,Socioeconômico!A$2:M$405,13,FALSE) -> 8.6096203 | H35: =(1*E35+F35+3*G35)/5/100 -> 0.25028781 | I35: =VLOOKUP(A35,Resultados!A$2:B433,2,FALSE) -> 0 | J35: =IFERROR(VLOOKUP(A35,Demográfico!A$2:E$400,5,FALSE)/(VLOOKUP(C35,Metodologia!A$2:G$9,7,FALSE))*D35,0) -> 0.79037495 | K35: =(J35*(1+H35)-I35) -> 0.98819616 | L35: 1 | M35: =VLOOKUP(A35,Demográfico!A$2:E$400,5,FALSE)*H35 -> 1732.2419 | N35: =IFERROR(FLOOR(K35,1),0) -> 0 | O35: =K35-N35 -> 0.98819616 | P35: =IFERROR(RANK(O35,O$2:O$400,0),0) -> 2 | Q35: =N35+IF(P35<P$1,1,0) -> 1 | S35: =VLOOKUP(A35,Demográfico!A$2:E$400,5,FALSE)*(H35) -> 1732.2419 | T35: =IFERROR(D35/D35,0) -> 1 | U35: =S35*T35 -> 1732.2419
A36: Ibiporã | B36: 51603 | C36: {=_xlfn.IFS(B36<5000, "P1",B36<20000, "P2",B36<70000, "P3",B36<100000, "P4",B36<200000,"M1",B36<500000,"M2",B36<1000000,"G1",B36>1000000,"G2")} -> P3 | D36: =VLOOKUP(C36,Metodologia!A$2:H$9,8,FALSE) -> 32.026801 | E36: =VLOOKUP(A36,Educacional!A$2:P$405,16,FALSE) -> 44.544379 | F36: =VLOOKUP(A36,Demográfico!A$2:L$405,12,FALSE) -> 56.082721 | G36: =VLOOKUP(A36,Socioeconômico!A$2:M$405,13,FALSE) -> 34.618049 | H36: =(1*E36+F36+3*G36)/5/100 -> 0.4089625 | I36: =VLOOKUP(A36,Resultados!A$2:B434,2,FALSE) -> 0 | J36: =IFERROR(VLOOKUP(A36,Demográfico!A$2:E$400,5,FALSE)/(VLOOKUP(C36,Metodologia!A$2:G$9,7,FALSE))*D36,0) -> 0.78066799 | K36: =(J36*(1+H36)-I36) -> 1.0999319 | L36: 1 | M36: =VLOOKUP(A36,Demográfico!A$2:E$400,5,FALSE)*H36 -> 2795.6676 | N36: =IFERROR(FLOOR(K36,1),0) -> 1 | O36: =K36-N36 -> 0.099931913 | P36: =IFERROR(RANK(O36,O$2:O$400,0),0) -> 306 | Q36: =N36+IF(P36<P$1,1,0) -> 1 | S36: =VLOOKUP(A36,Demográfico!A$2:E$400,5,FALSE)*(H36) -> 2795.6676 | T36: =IFERROR(D36/D36,0) -> 1 | U36: =S36*T36 -> 2795.6676
A37: Prudentópolis | B37: 49393 | C37: {=_xlfn.IFS(B37<5000, "P1",B37<20000, "P2",B37<70000, "P3",B37<100000, "P4",B37<200000,"M1",B37<500000,"M2",B37<1000000,"G1",B37>1000000,"G2")} -> P3 | D37: =VLOOKUP(C37,Metodologia!A$2:H$9,8,FALSE) -> 32.026801 | E37: =VLOOKUP(A37,Educacional!A$2:P$405,16,FALSE) -> 68.040211 | F37: =VLOOKUP(A37,Demográfico!A$2:L$405,12,FALSE) -> 44.15255 | G37: =VLOOKUP(A37,Socioeconômico!A$2:M$405,13,FALSE) -> 45.782371 | H37: =(1*E37+F37+3*G37)/5/100 -> 0.49907975 | I37: =VLOOKUP(A37,Resultados!A$2:B435,2,FALSE) -> 0 | J37: =IFERROR(VLOOKUP(A37,Demográfico!A$2:E$400,5,FALSE)/(VLOOKUP(C37,Metodologia!A$2:G$9,7,FALSE))*D37,0) -> 0.7525749 | K37: =(J37*(1+H37)-I37) -> 1.1281698 | L37: 1 | M37: =VLOOKUP(A37,Demográfico!A$2:E$400,5,FALSE)*H37 -> 3288.9355 | N37: =IFERROR(FLOOR(K37,1),0) -> 1 | O37: =K37-N37 -> 0.12816979 | P37: =IFERROR(RANK(O37,O$2:O$400,0),0) -> 266 | Q37: =N37+IF(P37<P$1,1,0) -> 1 | S37: =VLOOKUP(A37,Demográfico!A$2:E$400,5,FALSE)*(H37) -> 3288.9355 | T37: =IFERROR(D37/D37,0) -> 1 | U37: =S37*T37 -> 3288.9355
A38: Palmas | B38: 48247 | C38: {=_xlfn.IFS(B38<5000, "P1",B38<20000, "P2",B38<70000, "P3",B38<100000, "P4",B38<200000,"M1",B38<500000,"M2",B38<1000000,"G1",B38>1000000,"G2")} -> P3 | D38: =VLOOKUP(C38,Metodologia!A$2:H$9,8,FALSE) -> 32.026801 | E38: =VLOOKUP(A38,Educacional!A$2:P$405,16,FALSE) -> 71.469774 | F38: =VLOOKUP(A38,Demográfico!A$2:L$405,12,FALSE) -> 78.204143 | G38: =VLOOKUP(A38,Socioeconômico!A$2:M$405,13,FALSE) -> 38.16683 | H38: =(1*E38+F38+3*G38)/5/100 -> 0.52834881 | I38: =VLOOKUP(A38,Resultados!A$2:B436,2,FALSE) -> 0 | J38: =IFERROR(VLOOKUP(A38,Demográfico!A$2:E$400,5,FALSE)/(VLOOKUP(C38,Metodologia!A$2:G$9,7,FALSE))*D38,0) -> 0.88264817 | K38: =(J38*(1+H38)-I38) -> 1.3489943 | L38: 1 | M38: =VLOOKUP(A38,Demográfico!A$2:E$400,5,FALSE)*H38 -> 4083.608 | N38: =IFERROR(FLOOR(K38,1),0) -> 1 | O38: =K38-N38 -> 0.34899427 | P38: =IFERROR(RANK(O38,O$2:O$400,0),0) -> 115 | Q38: =N38+IF(P38<P$1,1,0) -> 1 | S38: =VLOOKUP(A38,Demográfico!A$2:E$400,5,FALSE)*(H38) -> 4083.608 | T38: =IFERROR(D38/D38,0) -> 1 | U38: =S38*T38 -> 4083.608
A39: Campina Grande do Sul | B39: 47825 | C39: {=_xlfn.IFS(B39<5000, "P1",B39<20000, "P2",B39<70000, "P3",B39<100000, "P4",B39<200000,"M1",B39<500000,"M2",B39<1000000,"G1",B39>1000000,"G2")} -> P3 | D39: =VLOOKUP(C39,Metodologia!A$2:H$9,8,FALSE) -> 32.026801 | E39: =VLOOKUP(A39,Educacional!A$2:P$405,16,FALSE) -> 62.356853 | F39: =VLOOKUP(A39,Demográfico!A$2:L$405,12,FALSE) -> 58.974281 | G39: =VLOOKUP(A39,Socioeconômico!A$2:M$405,13,FALSE) -> 32.621852 | H39: =(1*E39+F39+3*G39)/5/100 -> 0.43839338 | I39: =VLOOKUP(A39,Resultados!A$2:B437,2,FALSE) -> 0 | J39: =IFERROR(VLOOKUP(A39,Demográfico!A$2:E$400,5,FALSE)/(VLOOKUP(C39,Metodologia!A$2:G$9,7,FALSE))*D39,0) -> 0.82257921 | K39: =(J39*(1+H39)-I39) -> 1.1831925 | L39: 1 | M39: =VLOOKUP(A39,Demográfico!A$2:E$400,5,FALSE)*H39 -> 3157.7475 | N39: =IFERROR(FLOOR(K39,1),0) -> 1 | O39: =K39-N39 -> 0.18319249 | P39: =IFERROR(RANK(O39,O$2:O$400,0),0) -> 208 | Q39: =N39+IF(P39<P$1,1,0) -> 1 | S39: =VLOOKUP(A39,Demográfico!A$2:E$400,5,FALSE)*(H39) -> 3157.7475 | T39: =IFERROR(D39/D39,0) -> 1 | U39: =S39*T39 -> 3157.7475
A40: Paiçandu | B40: 45962 | C40: {=_xlfn.IFS(B40<5000, "P1",B40<20000, "P2",B40<70000, "P3",B40<100000, "P4",B40<200000,"M1",B40<500000,"M2",B40<1000000,"G1",B40>1000000,"G2")} -> P3 | D40: =VLOOKUP(C40,Metodologia!A$2:H$9,8,FALSE) -> 32.026801 | E40: =VLOOKUP(A40,Educacional!A$2:P$405,16,FALSE) -> 52.928465 | F40: =VLOOKUP(A40,Demográfico!A$2:L$405,12,FALSE) -> 52.388048 | G40: =VLOOKUP(A40,Socioeconômico!A$2:M$405,13,FALSE) -> 39.855772 | H40: =(1*E40+F40+3*G40)/5/100 -> 0.44976766 | I40: =VLOOKUP(A40,Resultados!A$2:B438,2,FALSE) -> 0 | J40: =IFERROR(VLOOKUP(A40,Demográfico!A$2:E$400,5,FALSE)/(VLOOKUP(C40,Metodologia!A$2:G$9,7,FALSE))*D40,0) -> 0.7275652 | K40: =(J40*(1+H40)-I40) -> 1.0548005 | L40: 1 | M40: =VLOOKUP(A40,Demográfico!A$2:E$400,5,FALSE)*H40 -> 2865.4698 | N40: =IFERROR(FLOOR(K40,1),0) -> 1 | O40: =K40-N40 -> 0.054800502 | P40: =IFERROR(RANK(O40,O$2:O$400,0),0) -> 375 | Q40: =N40+IF(P40<P$1,1,0) -> 1 | S40: =VLOOKUP(A40,Demográfico!A$2:E$400,5,FALSE)*(H40) -> 2865.4698 | T40: =IFERROR(D40/D40,0) -> 1 | U40: =S40*T40 -> 2865.4698
A41: Cornélio Procópio | B41: 45206 | C41: {=_xlfn.IFS(B41<5000, "P1",B41<20000, "P2",B41<70000, "P3",B41<100000, "P4",B41<200000,"M1",B41<500000,"M2",B41<1000000,"G1",B41>1000000,"G2")} -> P3 | D41: =VLOOKUP(C41,Metodologia!A$2:H$9,8,FALSE) -> 32.026801 | E41: =VLOOKUP(A41,Educacional!A$2:P$405,16,FALSE) -> 57.89864 | F41: =VLOOKUP(A41,Demográfico!A$2:L$405,12,FALSE) -> 33.916601 | G41: =VLOOKUP(A41,Socioeconômico!A$2:M$405,13,FALSE) -> 23.427535 | H41: =(1*E41+F41+3*G41)/5/100 -> 0.3241957 | I41: =VLOOKUP(A41,Resultados!A$2:B439,2,FALSE) -> 0 | J41: =IFERROR(VLOOKUP(A41,Demográfico!A$2:E$400,5,FALSE)/(VLOOKUP(C41,Metodologia!A$2:G$9,7,FALSE))*D41,0) -> 0.57042665 | K41: =(J41*(1+H41)-I41) -> 0.75535652 | L41: 1 | M41: =VLOOKUP(A41,Demográfico!A$2:E$400,5,FALSE)*H41 -> 1619.3575 | N41: =IFERROR(FLOOR(K41,1),0) -> 0 | O41: =K41-N41 -> 0.75535652 | P41: =IFERROR(RANK(O41,O$2:O$400,0),0) -> 26 | Q41: =N41+IF(P41<P$1,1,0) -> 1 | S41: =VLOOKUP(A41,Demográfico!A$2:E$400,5,FALSE)*(H41) -> 1619.3575 | T41: =IFERROR(D41/D41,0) -> 1 | U41: =S41*T41 -> 1619.3575
A42: Lapa | B42: 45003 | C42: {=_xlfn.IFS(B42<5000, "P1",B42<20000, "P2",B42<70000, "P3",B42<100000, "P4",B42<200000,"M1",B42<500000,"M2",B42<1000000,"G1",B42>1000000,"G2")} -> P3 | D42: =VLOOKUP(C42,Metodologia!A$2:H$9,8,FALSE) -> 32.026801 | E42: =VLOOKUP(A42,Educacional!A$2:P$405,16,FALSE) -> 66.202105 | F42: =VLOOKUP(A42,Demográfico!A$2:L$405,12,FALSE) -> 50.004905 | G42: =VLOOKUP(A42,Socioeconômico!A$2:M$405,13,FALSE) -> 33.922885 | H42: =(1*E42+F42+3*G42)/5/100 -> 0.43595133 | I42: =VLOOKUP(A42,Resultados!A$2:B440,2,FALSE) -> 0 | J42: =IFERROR(VLOOKUP(A42,Demográfico!A$2:E$400,5,FALSE)/(VLOOKUP(C42,Metodologia!A$2:G$9,7,FALSE))*D42,0) -> 0.67834521 | K42: =(J42*(1+H42)-I42) -> 0.9740707 | L42: 1 | M42: =VLOOKUP(A42,Demográfico!A$2:E$400,5,FALSE)*H42 -> 2589.5509 | N42: =IFERROR(FLOOR(K42,1),0) -> 0 | O42: =K42-N42 -> 0.9740707 | P42: =IFERROR(RANK(O42,O$2:O$400,0),0) -> 5 | Q42: =N42+IF(P42<P$1,1,0) -> 1 | S42: =VLOOKUP(A42,Demográfico!A$2:E$400,5,FALSE)*(H42) -> 2589.5509 | T42: =IFERROR(D42/D42,0) -> 1 | U42: =S42*T42 -> 2589.5509
A43: Dois Vizinhos | B43: 44869 | C43: {=_xlfn.IFS(B43<5000, "P1",B43<20000, "P2",B43<70000, "P3",B43<100000, "P4",B43<200000,"M1",B43<500000,"M2",B43<1000000,"G1",B43>1000000,"G2")} -> P3 | D43: =VLOOKUP(C43,Metodologia!A$2:H$9,8,FALSE) -> 32.026801 | E43: =VLOOKUP(A43,Educacional!A$2:P$405,16,FALSE) -> 45.691604 | F43: =VLOOKUP(A43,Demográfico!A$2:L$405,12,FALSE) -> 46.063271 | G43: =VLOOKUP(A43,Socioeconômico!A$2:M$405,13,FALSE) -> 18.167621 | H43: =(1*E43+F43+3*G43)/5/100 -> 0.29251547 | I43: =VLOOKUP(A43,Resultados!A$2:B441,2,FALSE) -> 0 | J43: =IFERROR(VLOOKUP(A43,Demográfico!A$2:E$400,5,FALSE)/(VLOOKUP(C43,Metodologia!A$2:G$9,7,FALSE))*D43,0) -> 0.66030168 | K43: =(J43*(1+H43)-I43) -> 0.85345014 | L43: 1 | M43: =VLOOKUP(A43,Demográfico!A$2:E$400,5,FALSE)*H43 -> 1691.3245 | N43: =IFERROR(FLOOR(K43,1),0) -> 0 | O43: =K43-N43 -> 0.85345014 | P43: =IFERROR(RANK(O43,O$2:O$400,0),0) -> 17 | Q43: =N43+IF(P43<P$1,1,0) -> 1 | S43: =VLOOKUP(A43,Demográfico!A$2:E$400,5,FALSE)*(H43) -> 1691.3245 | T43: =IFERROR(D43/D43,0) -> 1 | U43: =S43*T43 -> 1691.3245
... A93: Capanema | B93: 20481 | C93: {=_xlfn.IFS(B93<5000, "P1",B93<20000, "P2",B93<70000, "P3",B93<100000, "P4",B93<200000,"M1",B93<500000,"M2",B93<1000000,"G1",B93>1000000,"G2")} -> P3 | D93: =VLOOKUP(C93,Metodologia!A$2:H$9,8,FALSE) -> 32.026801 | E93: =VLOOKUP(A93,Educacional!A$2:P$405,16,FALSE) -> 41.989555 | F93: =VLOOKUP(A93,Demográfico!A$2:L$405,12,FALSE) -> 43.289169 | G93: =VLOOKUP(A93,Socioeconômico!A$2:M$405,13,FALSE) -> 23.666389 | H93: =(1*E93+F93+3*G93)/5/100 -> 0.31255578 | I93: =VLOOKUP(A93,Resultados!A$2:B491,2,FALSE) -> 0 | J93: =IFERROR(VLOOKUP(A93,Demográfico!A$2:E$400,5,FALSE)/(VLOOKUP(C93,Metodologia!A$2:G$9,7,FALSE))*D93,0) -> 0.28138764 | K93: =(J93*(1+H93)-I93) -> 0.36933697 | L93: 1 | M93: =VLOOKUP(A93,Demográfico!A$2:E$400,5,FALSE)*H93 -> 770.13744 | N93: =IFERROR(FLOOR(K93,1),0) -> 0 | O93: =K93-N93 -> 0.36933697 | P93: =IFERROR(RANK(O93,O$2:O$400,0),0) -> 105 | Q93: =N93+IF(P93<P$1,1,0) -> 1 | S93: =VLOOKUP(A93,Demográfico!A$2:E$400,5,FALSE)*(H93) -> 770.13744 | T93: =IFERROR(D93/D93,0) -> 1 | U93: =S93*T93 -> 770.13744
A94: Tibagi | B94: 19961 | C94: {=_xlfn.IFS(B94<5000, "P1",B94<20000, "P2",B94<70000, "P3",B94<100000, "P4",B94<200000,"M1",B94<500000,"M2",B94<1000000,"G1",B94>1000000,"G2")} -> P2 | D94: =VLOOKUP(C94,Metodologia!A$2:H$9,8,FALSE) -> 32.634343 | E94: =VLOOKUP(A94,Educacional!A$2:P$405,16,FALSE) -> 68.453183 | F94: =VLOOKUP(A94,Demográfico!A$2:L$405,12,FALSE) -> 55.537792 | G94: =VLOOKUP(A94,Socioeconômico!A$2:M$405,13,FALSE) -> 47.707526 | H94: =(2*E94+F94+2*G94)/5/100 -> 0.57571842 | I94: =VLOOKUP(A94,Resultados!A$2:B492,2,FALSE) -> 0 | J94: =IFERROR(VLOOKUP(A94,Demográfico!A$2:E$400,5,FALSE)/(VLOOKUP(C94,Metodologia!A$2:G$9,7,FALSE))*D94,0) -> 0.34476838 | K94: =(J94*(1+H94)-I94) -> 0.54325789 | L94: 1 | M94: =VLOOKUP(A94,Demográfico!A$2:E$400,5,FALSE)*H94 -> 1738.0939 | N94: =IFERROR(FLOOR(K94,1),0) -> 0 | O94: =K94-N94 -> 0.54325789 | P94: =IFERROR(RANK(O94,O$2:O$400,0),0) -> 57 | Q94: =N94+IF(P94<P$1,1,0) -> 1 | S94: =VLOOKUP(A94,Demográfico!A$2:E$400,5,FALSE)*(H94) -> 1738.0939 | T94: =IFERROR(D94/D94,0) -> 1 | U94: =S94*T94 -> 1738.0939
A95: Andirá | B95: 19878 | C95: {=_xlfn.IFS(B95<5000, "P1",B95<20000, "P2",B95<70000, "P3",B95<100000, "P4",B95<200000,"M1",B95<500000,"M2",B95<1000000,"G1",B95>1000000,"G2")} -> P2 | D95: =VLOOKUP(C95,Metodologia!A$2:H$9,8,FALSE) -> 32.634343 | E95: =VLOOKUP(A95,Educacional!A$2:P$405,16,FALSE) -> 48.312408 | F95: =VLOOKUP(A95,Demográfico!A$2:L$405,12,FALSE) -> 38.247281 | G95: =VLOOKUP(A95,Socioeconômico!A$2:M$405,13,FALSE) -> 44.161891 | H95: =(2*E95+F95+2*G95)/5/100 -> 0.44639176 | I95: =VLOOKUP(A95,Resultados!A$2:B493,2,FALSE) -> 0 | J95: =IFERROR(VLOOKUP(A95,Demográfico!A$2:E$400,5,FALSE)/(VLOOKUP(C95,Metodologia!A$2:G$9,7,FALSE))*D95,0) -> 0.27122388 | K95: =(J95*(1+H95)-I95) -> 0.39229599 | L95: 1 | M95: =VLOOKUP(A95,Demográfico!A$2:E$400,5,FALSE)*H95 -> 1060.1804 | N95: =IFERROR(FLOOR(K95,1),0) -> 0 | O95: =K95-N95 -> 0.39229599 | P95: =IFERROR(RANK(O95,O$2:O$400,0),0) -> 92 | Q95: =N95+IF(P95<P$1,1,0) -> 1 | S95: =VLOOKUP(A95,Demográfico!A$2:E$400,5,FALSE)*(H95) -> 1060.1804 | T95: =IFERROR(D95/D95,0) -> 1 | U95: =S95*T95 -> 1060.1804
A96: Ampére | B96: 19620 | C96: {=_xlfn.IFS(B96<5000, "P1",B96<20000, "P2",B96<70000, "P3",B96<100000, "P4",B96<200000,"M1",B96<500000,"M2",B96<1000000,"G1",B96>1000000,"G2")} -> P2 | D96: =VLOOKUP(C96,Metodologia!A$2:H$9,8,FALSE) -> 32.634343 | E96: =VLOOKUP(A96,Educacional!A$2:P$405,16,FALSE) -> 62.509269 | F96: =VLOOKUP(A96,Demográfico!A$2:L$405,12,FALSE) -> 43.254937 | G96: =VLOOKUP(A96,Socioeconômico!A$2:M$405,13,FALSE) -> 23.827714 | H96: =(2*E96+F96+2*G96)/5/100 -> 0.4318578 | I96: =VLOOKUP(A96,Resultados!A$2:B494,2,FALSE) -> 0 | J96: =IFERROR(VLOOKUP(A96,Demográfico!A$2:E$400,5,FALSE)/(VLOOKUP(C96,Metodologia!A$2:G$9,7,FALSE))*D96,0) -> 0.2912088 | K96: =(J96*(1+H96)-I96) -> 0.41696959 | L96: 1 | M96: =VLOOKUP(A96,Demográfico!A$2:E$400,5,FALSE)*H96 -> 1101.2374 | N96: =IFERROR(FLOOR(K96,1),0) -> 0 | O96: =K96-N96 -> 0.41696959 | P96: =IFERROR(RANK(O96,O$2:O$400,0),0) -> 83 | Q96: =N96+IF(P96<P$1,1,0) -> 1 | S96: =VLOOKUP(A96,Demográfico!A$2:E$400,5,FALSE)*(H96) -> 1101.2374 | T96: =IFERROR(D96/D96,0) -> 1 | U96: =S96*T96 -> 1101.2374
A97: Realeza | B97: 19247 | C97: {=_xlfn.IFS(B97<5000, "P1",B97<20000, "P2",B97<70000, "P3",B97<100000, "P4",B97<200000,"M1",B97<500000,"M2",B97<1000000,"G1",B97>1000000,"G2")} -> P2 | D97: =VLOOKUP(C97,Metodologia!A$2:H$9,8,FALSE) -> 32.634343 | E97: =VLOOKUP(A97,Educacional!A$2:P$405,16,FALSE) -> 42.905758 | F97: =VLOOKUP(A97,Demográfico!A$2:L$405,12,FALSE) -> 38.613378 | G97: =VLOOKUP(A97,Socioeconômico!A$2:M$405,13,FALSE) -> 27.481443 | H97: =(2*E97+F97+2*G97)/5/100 -> 0.35877556 | I97: =VLOOKUP(A97,Resultados!A$2:B495,2,FALSE) -> 0 | J97: =IFERROR(VLOOKUP(A97,Demográfico!A$2:E$400,5,FALSE)/(VLOOKUP(C97,Metodologia!A$2:G$9,7,FALSE))*D97,0) -> 0.27647706 | K97: =(J97*(1+H97)-I97) -> 0.37567027 | L97: 1 | M97: =VLOOKUP(A97,Demográfico!A$2:E$400,5,FALSE)*H97 -> 868.59563 | N97: =IFERROR(FLOOR(K97,1),0) -> 0 | O97: =K97-N97 -> 0.37567027 | P97: =IFERROR(RANK(O97,O$2:O$400,0),0) -> 99 | Q97: =N97+IF(P97<P$1,1,0) -> 1 | S97: =VLOOKUP(A97,Demográfico!A$2:E$400,5,FALSE)*(H97) -> 868.59563 | T97: =IFERROR(D97/D97,0) -> 1 | U97: =S97*T97 -> 868.59563
A98: Wenceslau Braz | B98: 19188 | C98: {=_xlfn.IFS(B98<5000, "P1",B98<20000, "P2",B98<70000, "P3",B98<100000, "P4",B98<200000,"M1",B98<500000,"M2",B98<1000000,"G1",B98>1000000,"G2")} -> P2 | D98: =VLOOKUP(C98,Metodologia!A$2:H$9,8,FALSE) -> 32.634343 | E98: =VLOOKUP(A98,Educacional!A$2:P$405,16,FALSE) -> 51.795151 | F98: =VLOOKUP(A98,Demográfico!A$2:L$405,12,FALSE) -> 49.091627 | G98: =VLOOKUP(A98,Socioeconômico!A$2:M$405,13,FALSE) -> 42.323099 | H98: =(2*E98+F98+2*G98)/5/100 -> 0.47465625 | I98: =VLOOKUP(A98,Resultados!A$2:B496,2,FALSE) -> 1 | J98: =IFERROR(VLOOKUP(A98,Demográfico!A$2:E$400,5,FALSE)/(VLOOKUP(C98,Metodologia!A$2:G$9,7,FALSE))*D98,0) -> 0.29497739 | K98: =(J98*(1+H98)-I98) -> -0.56500975 | L98: 1 | M98: =VLOOKUP(A98,Demográfico!A$2:E$400,5,FALSE)*H98 -> 1226.0371 | N98: =IFERROR(FLOOR(K98,1),0) -> -1 | O98: =K98-N98 -> 0.43499025 | P98: =IFERROR(RANK(O98,O$2:O$400,0),0) -> 81 | Q98: =N98+IF(P98<P$1,1,0) -> 0 | S98: =VLOOKUP(A98,Demográfico!A$2:E$400,5,FALSE)*(H98) -> 1226.0371 | T98: =IFERROR(D98/D98,0) -> 1 | U98: =S98*T98 -> 1226.0371
A99: Contenda | B99: 19128 | C99: {=_xlfn.IFS(B99<5000, "P1",B99<20000, "P2",B99<70000, "P3",B99<100000, "P4",B99<200000,"M1",B99<500000,"M2",B99<1000000,"G1",B99>1000000,"G2")} -> P2 | D99: =VLOOKUP(C99,Metodologia!A$2:H$9,8,FALSE) -> 32.634343 | E99: =VLOOKUP(A99,Educacional!A$2:P$405,16,FALSE) -> 81.430587 | F99: =VLOOKUP(A99,Demográfico!A$2:L$405,12,FALSE) -> 51.551121 | G99: =VLOOKUP(A99,Socioeconômico!A$2:M$405,13,FALSE) -> 39.239643 | H99: =(2*E99+F99+2*G99)/5/100 -> 0.58578316 | I99: =VLOOKUP(A99,Resultados!A$2:B497,2,FALSE) -> 1 | J99: =IFERROR(VLOOKUP(A99,Demográfico!A$2:E$400,5,FALSE)/(VLOOKUP(C99,Metodologia!A$2:G$9,7,FALSE))*D99,0) -> 0.31290671 | K99: =(J99*(1+H99)-I99) -> -0.50379781 | L99: 1 | M99: =VLOOKUP(A99,Demográfico!A$2:E$400,5,FALSE)*H99 -> 1605.0459 | N99: =IFERROR(FLOOR(K99,1),0) -> -1 | O99: =K99-N99 -> 0.49620219 | P99: =IFERROR(RANK(O99,O$2:O$400,0),0) -> 66 | Q99: =N99+IF(P99<P$1,1,0) -> 0 | S99: =VLOOKUP(A99,Demográfico!A$2:E$400,5,FALSE)*(H99) -> 1605.0459 | T99: =IFERROR(D99/D99,0) -> 1 | U99: =S99*T99 -> 1605.0459
A100: Cafelândia | B100: 18997 | C100: {=_xlfn.IFS(B100<5000, "P1",B100<20000, "P2",B100<70000, "P3",B100<100000, "P4",B100<200000,"M1",B100<500000,"M2",B100<1000000,"G1",B100>1000000,"G2")} -> P2 | D100: =VLOOKUP(C100,Metodologia!A$2:H$9,8,FALSE) -> 32.634343 | E100: =VLOOKUP(A100,Educacional!A$2:P$405,16,FALSE) -> 41.62516 | F100: =VLOOKUP(A100,Demográfico!A$2:L$405,12,FALSE) -> 44.569396 | G100: =VLOOKUP(A100,Socioeconômico!A$2:M$405,13,FALSE) -> 15.623612 | H100: =(2*E100+F100+2*G100)/5/100 -> 0.31813388 | I100: =VLOOKUP(A100,Resultados!A$2:B498,2,FALSE) -> 0 | J100: =IFERROR(VLOOKUP(A100,Demográfico!A$2:E$400,5,FALSE)/(VLOOKUP(C100,Metodologia!A$2:G$9,7,FALSE))*D100,0) -> 0.29337859 | K100: =(J100*(1+H100)-I100) -> 0.38671226 | L100: 1 | M100: =VLOOKUP(A100,Demográfico!A$2:E$400,5,FALSE)*H100 -> 817.28594 | N100: =IFERROR(FLOOR(K100,1),0) -> 0 | O100: =K100-N100 -> 0.38671226 | P100: =IFERROR(RANK(O100,O$2:O$400,0),0) -> 95 | Q100: =N100+IF(P100<P$1,1,0) -> 1 | S100: =VLOOKUP(A100,Demográfico!A$2:E$400,5,FALSE)*(H100) -> 817.28594 | T100: =IFERROR(D100/D100,0) -> 1 | U100: =S100*T100 -> 817.28594
A101: Altônia | B101: 18742 | C101: {=_xlfn.IFS(B101<5000, "P1",B101<20000, "P2",B101<70000, "P3",B101<100000, "P4",B101<200000,"M1",B101<500000,"M2",B101<1000000,"G1",B101>1000000,"G2")} -> P2 | D101: =VLOOKUP(C101,Metodologia!A$2:H$9,8,FALSE) -> 32.634343 | E101: =VLOOKUP(A101,Educacional!A$2:P$405,16,FALSE) -> 48.049698 | F101: =VLOOKUP(A101,Demográfico!A$2:L$405,12,FALSE) -> 36.16238 | G101: =VLOOKUP(A101,Socioeconômico!A$2:M$405,13,FALSE) -> 39.89883 | H101: =(2*E101+F101+2*G101)/5/100 -> 0.42411887 | I101: =VLOOKUP(A101,Resultados!A$2:B499,2,FALSE) -> 0 | J101: =IFERROR(VLOOKUP(A101,Demográfico!A$2:E$400,5,FALSE)/(VLOOKUP(C101,Metodologia!A$2:G$9,7,FALSE))*D101,0) -> 0.25706314 | K101: =(J101*(1+H101)-I101) -> 0.36608847 | L101: 1 | M101: =VLOOKUP(A101,Demográfico!A$2:E$400,5,FALSE)*H101 -> 954.69158 | N101: =IFERROR(FLOOR(K101,1),0) -> 0 | O101: =K101-N101 -> 0.36608847 | P101: =IFERROR(RANK(O101,O$2:O$400,0),0) -> 107 | Q101: =N101+IF(P101<P$1,1,0) -> 1 | S101: =VLOOKUP(A101,Demográfico!A$2:E$400,5,FALSE)*(H101) -> 954.69158 | T101: =IFERROR(D101/D101,0) -> 1 | U101: =S101*T101 -> 954.69158
A102: Matelândia | B102: 18450 | C102: {=_xlfn.IFS(B102<5000, "P1",B102<20000, "P2",B102<70000, "P3",B102<100000, "P4",B102<200000,"M1",B102<500000,"M2",B102<1000000,"G1",B102>1000000,"G2")} -> P2 | D102: =VLOOKUP(C102,Metodologia!A$2:H$9,8,FALSE) -> 32.634343 | E102: =VLOOKUP(A102,Educacional!A$2:P$405,16,FALSE) -> 41.307615 | F102: =VLOOKUP(A102,Demográfico!A$2:L$405,12,FALSE) -> 46.318301 | G102: =VLOOKUP(A102,Socioeconômico!A$2:M$405,13,FALSE) -> 10.7693 | H102: =(2*E102+F102+2*G102)/5/100 -> 0.30094426 | I102: =VLOOKUP(A102,Resultados!A$2:B500,2,FALSE) -> 0 | J102: =IFERROR(VLOOKUP(A102,Demográfico!A$2:E$400,5,FALSE)/(VLOOKUP(C102,Metodologia!A$2:G$9,7,FALSE))*D102,0) -> 0.28846801 | K102: =(J102*(1+H102)-I102) -> 0.3752808 | L102: 1 | M102: =VLOOKUP(A102,Demográfico!A$2:E$400,5,FALSE)*H102 -> 760.1852 | N102: =IFERROR(FLOOR(K102,1),0) -> 0 | O102: =K102-N102 -> 0.3752808 | P102: =IFERROR(RANK(O102,O$2:O$400,0),0) -> 100 | Q102: =N102+IF(P102<P$1,1,0) -> 1 | S102: =VLOOKUP(A102,Demográfico!A$2:E$400,5,FALSE)*(H102) -> 760.1852 | T102: =IFERROR(D102/D102,0) -> 1 | U102: =S102*T102 -> 760.1852
A103: Quitandinha | B103: 18398 | C103: {=_xlfn.IFS(B103<5000, "P1",B103<20000, "P2",B103<70000, "P3",B103<100000, "P4",B103<200000,"M1",B103<500000,"M2",B103<1000000,"G1",B103>1000000,"G2")} -> P2 | D103: =VLOOKUP(C103,Metodologia!A$2:H$9,8,FALSE) -> 32.634343 | E103: =VLOOKUP(A103,Educacional!A$2:P$405,16,FALSE) -> 70.431031 | F103: =VLOOKUP(A103,Demográfico!A$2:L$405,12,FALSE) -> 41.994459 | G103: =VLOOKUP(A103,Socioeconômico!A$2:M$405,13,FALSE) -> 39.747401 | H103: =(2*E103+F103+2*G103)/5/100 -> 0.52470265 | I103: =VLOOKUP(A103,Resultados!A$2:B501,2,FALSE) -> 0 | J103: =IFERROR(VLOOKUP(A103,Demográfico!A$2:E$400,5,FALSE)/(VLOOKUP(C103,Metodologia!A$2:G$9,7,FALSE))*D103,0) -> 0.27259428 | K103: =(J103*(1+H103)-I103) -> 0.41562522 | L103: 1 | M103: =VLOOKUP(A103,Demográfico!A$2:E$400,5,FALSE)*H103 -> 1252.4652 | N103: =IFERROR(FLOOR(K103,1),0) -> 0 | O103: =K103-N103 -> 0.41562522 | P103: =IFERROR(RANK(O103,O$2:O$400,0),0) -> 84 | Q103: =N103+IF(P103<P$1,1,0) -> 1 | S103: =VLOOKUP(A103,Demográfico!A$2:E$400,5,FALSE)*(H103) -> 1252.4652 | T103: =IFERROR(D103/D103,0) -> 1 | U103: =S103*T103 -> 1252.4652
A104: Morretes | B104: 18309 | C104: {=_xlfn.IFS(B104<5000, "P1",B104<20000, "P2",B104<70000, "P3",B104<100000, "P4",B104<200000,"M1",B104<500000,"M2",B104<1000000,"G1",B104>1000000,"G2")} -> P2 | D104: =VLOOKUP(C104,Metodologia!A$2:H$9,8,FALSE) -> 32.634343 | E104: =VLOOKUP(A104,Educacional!A$2:P$405,16,FALSE) -> 63.805332 | F104: =VLOOKUP(A104,Demográfico!A$2:L$405,12,FALSE) -> 37.61425 | G104: =VLOOKUP(A104,Socioeconômico!A$2:M$405,13,FALSE) -> 52.558011 | H104: =(2*E104+F104+2*G104)/5/100 -> 0.54068187 | I104: =VLOOKUP(A104,Resultados!A$2:B502,2,FALSE) -> 1 | J104: =IFERROR(VLOOKUP(A104,Demográfico!A$2:E$400,5,FALSE)/(VLOOKUP(C104,Metodologia!A$2:G$9,7,FALSE))*D104,0) -> 0.28469943 | K104: =(J104*(1+H104)-I104) -> -0.56136875 | L104: 1 | M104: =VLOOKUP(A104,Demográfico!A$2:E$400,5,FALSE)*H104 -> 1347.9199 | N104: =IFERROR(FLOOR(K104,1),0) -> -1 | O104: =K104-N104 -> 0.43863125 | P104: =IFERROR(RANK(O104,O$2:O$400,0),0) -> 79 | Q104: =N104+IF(P104<P$1,1,0) -> 0 | S104: =VLOOKUP(A104,Demográfico!A$2:E$400,5,FALSE)*(H104) -> 1347.9199 | T104: =IFERROR(D104/D104,0) -> 1 | U104: =S104*T104 -> 1347.9199
A105: Terra Roxa | B105: 18119 | C105: {=_xlfn.IFS(B105<5000, "P1",B105<20000, "P2",B105<70000, "P3",B105<100000, "P4",B105<200000,"M1",B105<500000,"M2",B105<1000000,"G1",B105>1000000,"G2")} -> P2 | D105: =VLOOKUP(C105,Metodologia!A$2:H$9,8,FALSE) -> 32.634343 | E105: =VLOOKUP(A105,Educacional!A$2:P$405,16,FALSE) -> 55.752293 | F105: =VLOOKUP(A105,Demográfico!A$2:L$405,12,FALSE) -> 40.571034 | G105: =VLOOKUP(A105,Socioeconômico!A$2:M$405,13,FALSE) -> 33.612981 | H105: =(2*E105+F105+2*G105)/5/100 -> 0.43860316 | I105: =VLOOKUP(A105,Resultados!A$2:B503,2,FALSE) -> 0 | J105: =IFERROR(VLOOKUP(A105,Demográfico!A$2:E$400,5,FALSE)/(VLOOKUP(C105,Metodologia!A$2:G$9,7,FALSE))*D105,0) -> 0.27464987 | K105: =(J105*(1+H105)-I105) -> 0.39511217 | L105: 1 | M105: =VLOOKUP(A105,Demográfico!A$2:E$400,5,FALSE)*H105 -> 1054.8406 | N105: =IFERROR(FLOOR(K105,1),0) -> 0 | O105: =K105-N105 -> 0.39511217 | P105: =IFERROR(RANK(O105,O$2:O$400,0),0) -> 89 | Q105: =N105+IF(P105<P$1,1,0) -> 1 | S105: =VLOOKUP(A105,Demográfico!A$2:E$400,5,FALSE)*(H105) -> 1054.8406 | T105: =IFERROR(D105/D105,0) -> 1 | U105: =S105*T105 -> 1054.8406
...

Sheet Educacional
B1: Código [-] | C1: Matriculas Creches | D1: População 0 a 4 | E1: Proporção | F1: Creche_Normalizado | G1: Matriculas Pré-Escola e Fundamental | H1: População 5 a 14 | I1: Proporção | J1: Matrícula_Normalizado | K1: Oferta Privado | L1: Oferta Total | M1: Total Oferta | N1: Privado_Normalizado | O1: FATOR EDUCAÇÃO
A2: Curitiba | B2: 4106902 | C2: 17725 | D2: 85003 | E2: 0.20852205 | F2: 67.953453 | G2: 233206 | H2: 202402 | I2: 1.1521922 | J2: 72.220046 | K2: 379 | L2: 604 | M2: 0.62748344 | N2: 37.251656 | O2: =(2*F2+J2+N2)/4 -> 61.344652 | P2: =(O2-O$402)/(O$403-O$402)*100 -> 56.511036
A3: Foz do Iguaçu | B3: 4108304 | C3: 4900 | D3: 18300 | E3: 0.26775956 | F3: 58.849583 | G3: 43678 | H3: 39481 | I3: 1.1063043 | J3: 75.341642 | K3: 29 | L3: 73 | M3: 0.39726027 | N3: 60.273973 | O3: =(2*F3+J3+N3)/4 -> 63.328695 | P3: =(O3-O$402)/(O$403-O$402)*100 -> 59.854018
A4: Maringá | B4: 4115200 | C4: 6614 | D4: 21680 | E4: 0.3050738 | F4: 53.114974 | G4: 53527 | H4: 45546 | I4: 1.1752294 | J4: 70.652899 | K4: 63 | L4: 125 | M4: 0.504 | N4: 49.6 | O4: =(2*F4+J4+N4)/4 -> 56.620712 | P4: =(O4-O$402)/(O$403-O$402)*100 -> 48.551508
A5: Cascavel | B5: 4104808 | C5: 5285 | D5: 23119 | E5: 0.22859985 | F5: 64.867812 | G5: 50655 | H5: 45120 | I5: 1.1226729 | J5: 74.228144 | K5: 46 | L5: 102 | M5: 0.45098039 | N5: 54.901961 | O5: =(2*F5+J5+N5)/4 -> 64.716432 | P5: =(O5-O$402)/(O$403-O$402)*100 -> 62.192264
A6: Londrina | B6: 4113700 | C6: 2282 | D6: 30194 | E6: 0.075577929 | F6: 88.384866 | G6: 77042 | H6: 66820 | I6: 1.1529782 | J6: 72.166579 | K6: 152 | L6: 187 | M6: 0.81283422 | N6: 18.716578 | O6: =(2*F6+J6+N6)/4 -> 66.913222 | P6: =(O6-O$402)/(O$403-O$402)*100 -> 65.89371
A7: Ponta Grossa | B7: 4119905 | C7: 4698 | D7: 22756 | E7: 0.20645105 | F7: 68.271734 | G7: 54861 | H7: 50454 | I7: 1.0873469 | J7: 76.63125 | K7: 37 | L7: 105 | M7: 0.35238095 | N7: 64.761905 | O7: =(2*F7+J7+N7)/4 -> 69.484156 | P7: =(O7-O$402)/(O$403-O$402)*100 -> 70.225565
A8: São José dos Pinhais | B8: 4125506 | C8: 3447 | D8: 21137 | E8: 0.16307896 | F8: 74.937339 | G8: 52037 | H8: 47016 | I8: 1.1067934 | J8: 75.308368 | K8: 37 | L8: 82 | M8: 0.45121951 | N8: 54.878049 | O8: =(2*F8+J8+N8)/4 -> 70.015273 | P8: =(O8-O$402)/(O$403-O$402)*100 -> 71.120463
A9: Colombo | B9: 4105805 | C9: 3929 | D9: 14801 | E9: 0.26545504 | F9: 59.203752 | G9: 37968 | H9: 33632 | I9: 1.1289248 | J9: 73.802844 | K9: 14 | L9: 60 | M9: 0.23333333 | N9: 76.666667 | O9: =(2*F9+J9+N9)/4 -> 67.219254 | P9: =(O9-O$402)/(O$403-O$402)*100 -> 66.409354
A10: Araucária | B10: 4101804 | C10: 3972 | D10: 10075 | E10: 0.39424318 | F10: 39.411049 | G10: 25488 | H10: 22332 | I10: 1.1413219 | J10: 72.959516 | K10: 12 | L10: 49 | M10: 0.24489796 | N10: 75.510204 | O10: =(2*F10+J10+N10)/4 -> 56.822954 | P10: =(O10-O$402)/(O$403-O$402)*100 -> 48.892273
A11: Guarapuava | B11: 4109401 | C11: 2947 | D11: 12791 | E11: 0.23039637 | F11: 64.591715 | G11: 29194 | H11: 25554 | I11: 1.1424435 | J11: 72.883218 | K11: 22 | L11: 48 | M11: 0.45833333 | N11: 54.166667 | O11: =(2*F11+J11+N11)/4 -> 64.058329 | P11: =(O11-O$402)/(O$403-O$402)*100 -> 61.083403
A12: Fazenda Rio Grande | B12: 4107652 | C12: 1781 | D12: 11090 | E12: 0.16059513 | F12: 75.319064 | G12: 26388 | H12: 24618 | I12: 1.0718986 | J12: 77.682144 | K12: 7 | L12: 20 | M12: 0.35 | N12: 65 | O12: =(2*F12+J12+N12)/4 -> 73.330068 | P12: =(O12-O$402)/(O$403-O$402)*100 -> 76.705674
A13: Toledo | B13: 4127700 | C13: 3483 | D13: 9412 | E13: 0.3700595 | F13: 43.127698 | G13: 21824 | H13: 19560 | I13: 1.1157464 | J13: 74.699326 | K13: 11 | L13: 41 | M13: 0.26829268 | N13: 73.170732 | O13: =(2*F13+J13+N13)/4 -> 58.531364 | P13: =(O13-O$402)/(O$403-O$402)*100 -> 51.77083
... A400: Sulina | B400: 4126652 | C400: 0 | D400: 209 | E400: 0 | F400: 100 | G400: 441 | H400: 415 | I400: 1.0626506 | J400: 78.311254 | K400: 1 | L400: 1 | M400: 1 | N400: 0 | O400: =(2*F400+J400+N400)/4 -> 69.577814 | P400: =(O400-O$402)/(O$403-O$402)*100 -> 70.383372
A402: Quartil Minimo | E402: =QUARTILE(E1:E400,0) -> 0 | I402: =QUARTILE(I1:I400,0) -> 0.74382315 | J402: =QUARTILE(J1:J400,0) -> 0 | K402: =QUARTILE(K1:K400,0) -> 0 | L402: =QUARTILE(L1:L400,0) -> 1 | M402: =QUARTILE(M1:M400,0) -> 0 | N402: =QUARTILE(N1:N400,0) -> 0 | O402: =QUARTILE(O1:O400,0) -> 27.805636
A403: Quartil Máximo | E403: =QUARTILE(E2:E400,4) -> 0.65068493 | I403: =QUARTILE(I2:I400,4) -> 2.2138365 | J403: =QUARTILE(J2:J400,4) -> 100 | K403: =QUARTILE(K2:K400,4) -> 379 | L403: =QUARTILE(L2:L400,4) -> 604 | M403: =QUARTILE(M2:M400,4) -> 1 | N403: =QUARTILE(N2:N400,4) -> 100 | O403: =QUARTILE(O2:O400,4) -> 87.155133

Sheet Demográfico
B1: Código [-] | C1: Mortalidade Infantil | D1: MI_Normalizado | E1: População 0 a 4 | F1: População Total | G1: Proporção | H1: Proporção_Normalizado | I1: Taxa de Natalidade | J1: Natalidade_Normalizado | K1: FATOR DEMOGRÁFICO
A2: Curitiba | B2: 4106902 | C2: 7.1 | D2: 12.778978 | E2: 202402 | F2: 1773718 | G2: 0.11411171 | H2: 66.323434 | I2: 10.37 | J2: 55.573419 | K2: =(D2+H2+J2)/3 -> 44.891944 | L2: =(K2-K$401)/(K$402-K$401)*100 -> 29.902254 | M2: =VLOOKUP(A2,Dados!A$2:C$400,3,FALSE) -> G2
A3: Foz do Iguaçu | B3: 4108304 | C3: 9.14 | D3: 16.450684 | E3: 39481 | F3: 285415 | G3: 0.1383284 | H3: 80.398534 | I3: 14.08 | J3: 75.45552 | K3: =(D3+H3+J3)/3 -> 57.434913 | L3: =(K3-K$401)/(K$402-K$401)*100 -> 53.393821 | M3: =VLOOKUP(A3,Dados!A$2:C$400,3,FALSE) -> M2
A4: Maringá | B4: 4115200 | C4: 7.29 | D4: 13.12095 | E4: 45546 | F4: 409657 | G4: 0.11118082 | H4: 64.619953 | I4: 11.36 | J4: 60.878885 | K4: =(D4+H4+J4)/3 -> 46.206596 | L4: =(K4-K$401)/(K$402-K$401)*100 -> 32.36445 | M4: =VLOOKUP(A4,Dados!A$2:C$400,3,FALSE) -> M2
A5: Cascavel | B5: 4104808 | C5: 7.09 | D5: 12.760979 | E5: 45120 | F5: 348051 | G5: 0.12963617 | H5: 75.346483 | I5: 13.61 | J5: 72.936763 | K5: =(D5+H5+J5)/3 -> 53.681408 | L5: =(K5-K$401)/(K$402-K$401)*100 -> 46.363931 | M5: =VLOOKUP(A5,Dados!A$2:C$400,3,FALSE) -> M2
A6: Londrina | B6: 4113700 | C6: 11.84 | D6: 21.310295 | E6: 66820 | F6: 555965 | G6: 0.12018742 | H6: 69.854727 | I6: 11 | J6: 58.949625 | K6: =(D6+H6+J6)/3 -> 50.038216 | L6: =(K6-K$401)/(K$402-K$401)*100 -> 39.540641 | M6: =VLOOKUP(A6,Dados!A$2:C$400,3,FALSE) -> G1
A7: Ponta Grossa | B7: 4119905 | C7: 9.08 | D7: 16.342693 | E7: 50454 | F7: 358371 | G7: 0.14078706 | H7: 81.827545 | I7: 13.01 | J7: 69.721329 | K7: =(D7+H7+J7)/3 -> 55.963856 | L7: =(K7-K$401)/(K$402-K$401)*100 -> 50.638697 | M7: =VLOOKUP(A7,Dados!A$2:C$400,3,FALSE) -> M2
A8: São José dos Pinhais | B8: 4125506 | C8: 9.19 | D8: 16.540677 | E8: 47016 | F8: 329628 | G8: 0.14263351 | H8: 82.900731 | I8: 12.92 | J8: 69.239014 | K8: =(D8+H8+J8)/3 -> 56.226807 | L8: =(K8-K$401)/(K$402-K$401)*100 -> 51.131176 | M8: =VLOOKUP(A8,Dados!A$2:C$400,3,FALSE) -> M2
A9: Colombo | B9: 4105805 | C9: 8.21 | D9: 14.776818 | E9: 33632 | F9: 232212 | G9: 0.14483317 | H9: 84.179204 | I9: 12.73 | J9: 68.220793 | K9: =(D9+H9+J9)/3 -> 55.725605 | L9: =(K9-K$401)/(K$402-K$401)*100 -> 50.192481 | M9: =VLOOKUP(A9,Dados!A$2:C$400,3,FALSE) -> M2
A10: Araucária | B10: 4101804 | C10: 6.4 | D10: 11.519078 | E10: 22332 | F10: 151666 | G10: 0.1472446 | H10: 85.580765 | I10: 12.86 | J10: 68.917471 | K10: =(D10+H10+J10)/3 -> 55.339105 | L10: =(K10-K$401)/(K$402-K$401)*100 -> 49.468609 | M10: =VLOOKUP(A10,Dados!A$2:C$400,3,FALSE) -> M1
A11: Guarapuava | B11: 4109401 | C11: 9.89 | D11: 17.800576 | E11: 25554 | F11: 182093 | G11: 0.14033488 | H11: 81.564733 | I11: 14.27 | J11: 76.473741 | K11: =(D11+H11+J11)/3 -> 58.613017 | L11: =(K11-K$401)/(K$402-K$401)*100 -> 55.600277 | M11: =VLOOKUP(A11,Dados!A$2:C$400,3,FALSE) -> M1
A12: Fazenda Rio Grande | B12: 4107652 | C12: 9.92 | D12: 17.854572 | E12: 24618 | F12: 148873 | G12: 0.16536242 | H12: 96.111113 | I12: 12.91 | J12: 69.185423 | K12: =(D12+H12+J12)/3 -> 61.050369 | L12: =(K12-K$401)/(K$402-K$401)*100 -> 60.165164 | M12: =VLOOKUP(A12,Dados!A$2:C$400,3,FALSE) -> M1
A13: Toledo | B13: 4127700 | C13: 7.59 | D13: 13.660907 | E13: 19560 | F13: 150470 | G13: 0.12999269 | H13: 75.553695 | I13: 13.39 | J13: 71.757771 | K13: =(D13+H13+J13)/3 -> 53.657458 | L13: =(K13-K$401)/(K$402-K$401)*100 -> 46.319074 | M13: =VLOOKUP(A13,Dados!A$2:C$400,3,FALSE) -> M1
... A400: Sulina | B400: 4126652 | C400: 0 | D400: 0 | E400: 415 | F400: 3440 | G400: 0.12063953 | H400: 70.117502 | I400: 12.79 | J400: 68.542337 | K400: =(D400+H400+J400)/3 -> 46.219946 | L400: =(K400-K$401)/(K$402-K$401)*100 -> 32.389453 | M400: =VLOOKUP(A400,Dados!A$2:C$400,3,FALSE) -> P1
C401: 0 | D401: 0 | E401: 176 | F401: 1323 | G401: 0.10421412 | H401: 60.570807 | I401: 3.56 | J401: 19.078242 | K401: =QUARTILE(K2:K400,0) -> 28.926085 | M401: =VLOOKUP(A401,Dados!A$2:C$400,3,FALSE) -> #N/A
C402: 55.56 | D402: 100 | E402: 202402 | F402: 1773718 | G402: 0.17205338 | H402: 100 | I402: 18.66 | J402: 100 | K402: =QUARTILE(K2:K400,4) -> 82.319581 | M402: =VLOOKUP(A402,Dados!A$2:C$400,3,FALSE) -> #N/A
E405: =SUM(E$2:E$400) -> 1497164

Sheet Socioeconômico
B1: Código | C1: [-] | D1: Proporção | E1: Desnutrição_Normalizado | F1: CADUnico | G1: População 5 a 14 | H1: Proporção | I1: CADUnico_Normalizado | J1: IPDM-R | K1: Oferta Total | L1: FATOR SOCIOECONÔMICO
A2: Curitiba | B2: 410690 | C2: 2 | D2: 0.039521186 | E2: 3.9521186 | F2: 23579 | G2: 185447 | H2: 0.12714684 | I2: 16.666237 | J2: 0.83316572 | K2: 0 | L2: =(K2+I2+E2)/3 -> 6.8727851 | M2: =(L2-L$402)/(L$403-L$402)*100 -> 0
A3: Foz do Iguaçu | B3: 410830 | C3: 4 | D3: 0.038194444 | E3: 3.8194444 | F3: 9447 | G3: 38190 | H3: 0.24736842 | I3: 37.344134 | J3: 0.59942021 | K3: 38.905252 | L3: =(K3+I3+E3)/3 -> 26.68961 | M3: =(L3-L$402)/(L$403-L$402)*100 -> 30.757393
A4: Maringá | B4: 411520 | C4: 0 | D4: 0.03707518 | E4: 3.707518 | F4: 5145 | G4: 44828 | H4: 0.11477202 | I4: 14.537789 | J4: 0.67167541 | K4: 26.878896 | L4: =(K4+I4+E4)/3 -> 15.041401 | M4: =(L4-L$402)/(L$403-L$402)*100 -> 12.678385
A5: Cascavel | B5: 410480 | C5: 8 | D5: 0.024749868 | E5: 2.4749868 | F5: 6125 | G5: 46503 | H5: 0.13171193 | I5: 17.451425 | J5: 0.6886966 | K5: 24.045842 | L5: =(K5+I5+E5)/3 -> 14.657418 | M5: =(L5-L$402)/(L$403-L$402)*100 -> 12.08241
A6: Londrina | B6: 411370 | C6: 0 | D6: 0.048085901 | E6: 4.8085901 | F6: 12581 | G6: 63953 | H6: 0.19672259 | I6: 28.633142 | J6: 0.62865828 | K6: 34.038786 | L6: =(K6+I6+E6)/3 -> 22.493506 | M6: =(L6-L$402)/(L$403-L$402)*100 -> 24.244683
A7: Ponta Grossa | B7: 411990 | C7: 5 | D7: 0.021359223 | E7: 2.1359223 | F7: 8465 | G7: 48349 | H7: 0.17508118 | I7: 24.910858 | J7: 0.59499454 | K7: 39.641873 | L7: =(K7+I7+E7)/3 -> 22.229551 | M7: =(L7-L$402)/(L$403-L$402)*100 -> 23.835003
A8: São José dos Pinhais | B8: 412550 | C8: 6 | D8: 0.065654493 | E8: 6.5654493 | F8: 6404 | G8: 45199 | H8: 0.14168455 | I8: 19.166697 | J8: 0.69416041 | K8: 23.136431 | L8: =(K8+I8+E8)/3 -> 16.289526 | M8: =(L8-L$402)/(L$403-L$402)*100 -> 14.61558
A9: Colombo | B9: 410580 | C9: 5 | D9: 0.056998557 | E9: 5.6998557 | F9: 6643 | G9: 31809 | H9: 0.20884027 | I9: 30.71736 | J9: 0.49567605 | K9: 56.172718 | L9: =(K9+I9+E9)/3 -> 30.863311 | M9: =(L9-L$402)/(L$403-L$402)*100 -> 37.235331
A10: Araucária | B10: 410180 | C10: 4 | D10: 0.034263959 | E10: 3.4263959 | F10: 3496 | G10: 21525 | H10: 0.1624158 | I10: 22.732434 | J10: 0.67840839 | K10: 25.75824 | L10: =(K10+I10+E10)/3 -> 17.30569 | M10: =(L10-L$402)/(L$403-L$402)*100 -> 16.192753
A11: Guarapuava | B11: 410940 | C11: 1 | D11: 0.06445993 | E11: 6.445993 | F11: 6158 | G11: 25977 | H11: 0.23705586 | I11: 35.570392 | J11: 0.63210581 | K11: 33.46497 | L11: =(K11+I11+E11)/3 -> 25.160452 | M11: =(L11-L$402)/(L$403-L$402)*100 -> 28.384009
A12: Fazenda Rio Grande | B12: 410765 | C12: 2 | D12: 0.054669704 | E12: 5.4669704 | F12: 3274 | G12: 23587 | H12: 0.13880527 | I12: 18.671467 | J12: 0.53134107 | K12: 50.236533 | L12: =(K12+I12+E12)/3 -> 24.791657 | M12: =(L12-L$402)/(L$403-L$402)*100 -> 27.811608
