Workbook

Sheet CI
A1: MUNICÍPIO | B1: POPULAÇÃO | C1: PORTE DO MUNICÍPIO | D1: FAIXA DE CRECHES | E1: FAIXA 2 | F1: FATOR EDUCAÇÃO | G1: FATOR DEMOGRÁFICO | H1: FATOR SOCIOECONÔMICO | I1: PCM | J1: PROPORÇÃO CRECHES | K1: PROPORÇÃO 2 | L1: APROX. CRECHES | Q1: =SUM(L$2:L$400)-(SUM(O$2:O$400)) -> 192 | R1: TOTAL CRECHES
A2: Curitiba | B2: 1773718 | C2: {=_xlfn.IFS(B2<20000, "P1",B2<40000, "P2",B2<70000, "P3",B2<100000, "P4",B2<200000,"M1",B2<500000,"M2",B2<1000000,"G1",B2>1000000,"G2")} -> G2 | D2: =VLOOKUP(C2,Controle!A$2:H$9,8,FALSE) -> 23.689077 | E2: =VLOOKUP(C2,Controle!A$16:H$23,8,FALSE) -> 8.1989249 | F2: =VLOOKUP(A2,Educacional!A$2:P$405,16,FALSE) -> 56.511036 | G2: =VLOOKUP(A2,Demográfico!A$2:L$405,12,FALSE) -> 29.902254 | H2: =VLOOKUP(A2,Socioeconômico!A$2:M$405,13,FALSE) -> 0 | I2: =(2*F2+G2+2*H2)/5/100 -> 0.28584865 | J2: =VLOOKUP(A2,Demográfico!A$2:E$400,5,FALSE)/(VLOOKUP(C2,Controle!A$2:G$9,7,FALSE))*D2 -> 23.689077 | K2: =VLOOKUP(A2,Demográfico!A$2:E$400,5,FALSE)/(VLOOKUP(C2,Controle!A$16:G$24,7,FALSE))*E2 -> 8.1989249 | L2: =((J2*(1+I2))+3*(I2+K2))/4 -> 13.978722 | M2: =INT(L2) -> 13 | N2: =VLOOKUP(A2,Demográfico!A$2:E$400,5,FALSE)*I2 -> 57856.339 | O2: =FLOOR(L2,1) -> 13 | P2: =L2-O2 -> 0.97872203 | Q2: =RANK(P2,P$2:P$400,0) -> 3 | R2: =O2+IF(Q2<Q$1,1,0) -> 14 | T2: =VLOOKUP(A2,Demográfico!A$2:E$400,5,FALSE)*(I2) -> 57856.339
A3: Londrina | B3: 555965 | C3: {=_xlfn.IFS(B3<20000, "P1",B3<40000, "P2",B3<70000, "P3",B3<100000, "P4",B3<200000,"M1",B3<500000,"M2",B3<1000000,"G1",B3>1000000,"G2")} -> G1 | D3: =VLOOKUP(C3,Controle!A$2:H$9,8,FALSE) -> 7.8205952 | E3: =VLOOKUP(C3,Controle!A$16:H$23,8,FALSE) -> 2.7067527 | F3: =VLOOKUP(A3,Educacional!A$2:P$405,16,FALSE) -> 65.89371 | G3: =VLOOKUP(A3,Demográfico!A$2:L$405,12,FALSE) -> 39.540641 | H3: =VLOOKUP(A3,Socioeconômico!A$2:M$405,13,FALSE) -> 24.244683 | I3: =(2*F3+G3+2*H3)/5/100 -> 0.43963486 | J3: =VLOOKUP(A3,Demográfico!A$2:E$400,5,FALSE)/(VLOOKUP(C3,Controle!A$2:G$9,7,FALSE))*D3 -> 7.8205952 | K3: =VLOOKUP(A3,Demográfico!A$2:E$400,5,FALSE)/(VLOOKUP(C3,Controle!A$16:G$24,7,FALSE))*E3 -> 2.7067527 | L3: =((J3*(1+I3))+3*(I3+K3))/4 -> 5.174491 | M3: 4 | N3: =VLOOKUP(A3,Demográfico!A$2:E$400,5,FALSE)*I3 -> 29376.401 | O3: =FLOOR(L3,1) -> 5 | P3: =L3-O3 -> 0.17449104 | Q3: =RANK(P3,P$2:P$400,0) -> 393 | R3: =O3+IF(Q3<Q$1,1,0) -> 5 | T3: =VLOOKUP(A3,Demográfico!A$2:E$400,5,FALSE)*(I3) -> 29376.401
A4: Maringá | B4: 409657 | C4: {=_xlfn.IFS(B4<20000, "P1",B4<40000, "P2",B4<70000, "P3",B4<100000, "P4",B4<200000,"M1",B4<500000,"M2",B4<1000000,"G1",B4>1000000,"G2")} -> M2 | D4: =VLOOKUP(C4,Controle!A$2:H$9,8,FALSE) -> 30.576514 | E4: =VLOOKUP(C4,Controle!A$16:H$23,8,FALSE) -> 10.582706 | F4: =VLOOKUP(A4,Educacional!A$2:P$405,16,FALSE) -> 48.551508 | G4: =VLOOKUP(A4,Demográfico!A$2:L$405,12,FALSE) -> 32.36445 | H4: =VLOOKUP(A4,Socioeconômico!A$2:M$405,13,FALSE) -> 12.678385 | I4: =(2*F4+G4+2*H4)/5/100 -> 0.30964847 | J4: =VLOOKUP(A4,Demográfico!A$2:E$400,5,FALSE)/(VLOOKUP(C4,Controle!A$2:G$9,7,FALSE))*D4 -> 5.3306918 | K4: =VLOOKUP(A4,Demográfico!A$2:E$400,5,FALSE)/(VLOOKUP(C4,Controle!A$16:G$24,7,FALSE))*E4 -> 1.8449829 | L4: =((J4*(1+I4))+3*(I4+K4))/4 -> 3.3613066 | M4: 3 | N4: =VLOOKUP(A4,Demográfico!A$2:E$400,5,FALSE)*I4 -> 14103.249 | O4: =FLOOR(L4,1) -> 3 | P4: =L4-O4 -> 0.36130665 | Q4: =RANK(P4,P$2:P$400,0) -> 318 | R4: =O4+IF(Q4<Q$1,1,0) -> 3 | T4: =VLOOKUP(A4,Demográfico!A$2:E$400,5,FALSE)*(I4) -> 14103.249
A5: Ponta Grossa | B5: 358371 | C5: {=_xlfn.IFS(B5<20000, "P1",B5<40000, "P2",B5<70000, "P3",B5<100000, "P4",B5<200000,"M1",B5<500000,"M2",B5<1000000,"G1",B5>1000000,"G2")} -> M2 | D5: =VLOOKUP(C5,Controle!A$2:H$9,8,FALSE) -> 30.576514 | E5: =VLOOKUP(C5,Controle!A$16:H$23,8,FALSE) -> 10.582706 | F5: =VLOOKUP(A5,Educacional!A$2:P$405,16,FALSE) -> 70.225565 | G5: =VLOOKUP(A5,Demográfico!A$2:L$405,12,FALSE) -> 50.638697 | H5: =VLOOKUP(A5,Socioeconômico!A$2:M$405,13,FALSE) -> 23.835003 | I5: =(2*F5+G5+2*H5)/5/100 -> 0.47751966 | J5: =VLOOKUP(A5,Demográfico!A$2:E$400,5,FALSE)/(VLOOKUP(C5,Controle!A$2:G$9,7,FALSE))*D5 -> 5.9051229 | K5: =VLOOKUP(A5,Demográfico!A$2:E$400,5,FALSE)/(VLOOKUP(C5,Controle!A$16:G$24,7,FALSE))*E5 -> 2.0437968 | L5: =((J5*(1+I5))+3*(I5+K5))/4 -> 4.0722211 | M5: 3 | N5: =VLOOKUP(A5,Demográfico!A$2:E$400,5,FALSE)*I5 -> 24092.777 | O5: =FLOOR(L5,1) -> 4 | P5: =L5-O5 -> 0.07222113 | Q5: =RANK(P5,P$2:P$400,0) -> 397 | R5: =O5+IF(Q5<Q$1,1,0) -> 4 | T5: =VLOOKUP(A5,Demográfico!A$2:E$400,5,FALSE)*(I5) -> 24092.777
A6: Cascavel | B6: 348051 | C6: {=_xlfn.IFS(B6<20000, "P1",B6<40000, "P2",B6<70000, "P3",B6<100000, "P4",B6<200000,"M1",B6<500000,"M2",B6<1000000,"G1",B6>1000000,"G2")} -> M2 | D6: =VLOOKUP(C6,Controle!A$2:H$9,8,FALSE) -> 30.576514 | E6: =VLOOKUP(C6,Controle!A$16:H$23,8,FALSE) -> 10.582706 | F6: =VLOOKUP(A6,Educacional!A$2:P$405,16,FALSE) -> 62.192264 | G6: =VLOOKUP(A6,Demográfico!A$2:L$405,12,FALSE) -> 46.363931 | H6: =VLOOKUP(A6,Socioeconômico!A$2:M$405,13,FALSE) -> 12.08241 | I6: =(2*F6+G6+2*H6)/5/100 -> 0.38982656 | J6: =VLOOKUP(A6,Demográfico!A$2:E$400,5,FALSE)/(VLOOKUP(C6,Controle!A$2:G$9,7,FALSE))*D6 -> 5.2808329 | K6: =VLOOKUP(A6,Demográfico!A$2:E$400,5,FALSE)/(VLOOKUP(C6,Controle!A$16:G$24,7,FALSE))*E6 -> 1.8277265 | L6: =((J6*(1+I6))+3*(I6+K6))/4 -> 3.4980252 | M6: 3 | N6: =VLOOKUP(A6,Demográfico!A$2:E$400,5,FALSE)*I6 -> 17588.974 | O6: =FLOOR(L6,1) -> 3 | P6: =L6-O6 -> 0.49802522 | Q6: =RANK(P6,P$2:P$400,0) -> 156 | R6: =O6+IF(Q6<Q$1,1,0) -> 4 | T6: =VLOOKUP(A6,Demográfico!A$2:E$400,5,FALSE)*(I6) -> 17588.974
A7: São José dos Pinhais | B7: 329628 | C7: {=_xlfn.IFS(B7<20000, "P1",B7<40000, "P2",B7<70000, "P3",B7<100000, "P4",B7<200000,"M1",B7<500000,"M2",B7<1000000,"G1",B7>1000000,"G2")} -> M2 | D7: =VLOOKUP(C7,Controle!A$2:H$9,8,FALSE) -> 30.576514 | E7: =VLOOKUP(C7,Controle!A$16:H$23,8,FALSE) -> 10.582706 | F7: =VLOOKUP(A7,Educacional!A$2:P$405,16,FALSE) -> 71.120463 | G7: =VLOOKUP(A7,Demográfico!A$2:L$405,12,FALSE) -> 51.131176 | H7: =VLOOKUP(A7,Socioeconômico!A$2:M$405,13,FALSE) -> 14.61558 | I7: =(2*F7+G7+2*H7)/5/100 -> 0.44520652 | J7: =VLOOKUP(A7,Demográfico!A$2:E$400,5,FALSE)/(VLOOKUP(C7,Controle!A$2:G$9,7,FALSE))*D7 -> 5.5027402 | K7: =VLOOKUP(A7,Demográfico!A$2:E$400,5,FALSE)/(VLOOKUP(C7,Controle!A$16:G$24,7,FALSE))*E7 -> 1.9045299 | L7: =((J7*(1+I7))+3*(I7+K7))/4 -> 3.7504513 | M7: 3 | N7: =VLOOKUP(A7,Demográfico!A$2:E$400,5,FALSE)*I7 -> 20931.83 | O7: =FLOOR(L7,1) -> 3 | P7: =L7-O7 -> 0.75045132 | Q7: =RANK(P7,P$2:P$400,0) -> 23 | R7: =O7+IF(Q7<Q$1,1,0) -> 4 | T7: =VLOOKUP(A7,Demográfico!A$2:E$400,5,FALSE)*(I7) -> 20931.83
A8: Foz do Iguaçu | B8: 285415 | C8: {=_xlfn.IFS(B8<20000, "P1",B8<40000, "P2",B8<70000, "P3",B8<100000, "P4",B8<200000,"M1",B8<500000,"M2",B8<1000000,"G1",B8>1000000,"G2")} -> M2 | D8: =VLOOKUP(C8,Controle!A$2:H$9,8,FALSE) -> 30.576514 | E8: =VLOOKUP(C8,Controle!A$16:H$23,8,FALSE) -> 10.582706 | F8: =VLOOKUP(A8,Educacional!A$2:P$405,16,FALSE) -> 59.854018 | G8: =VLOOKUP(A8,Demográfico!A$2:L$405,12,FALSE) -> 53.393821 | H8: =VLOOKUP(A8,Socioeconômico!A$2:M$405,13,FALSE) -> 30.757393 | I8: =(2*F8+G8+2*H8)/5/100 -> 0.46923329 | J8: =VLOOKUP(A8,Demográfico!A$2:E$400,5,FALSE)/(VLOOKUP(C8,Controle!A$2:G$9,7,FALSE))*D8 -> 4.6208458 | K8: =VLOOKUP(A8,Demográfico!A$2:E$400,5,FALSE)/(VLOOKUP(C8,Controle!A$16:G$24,7,FALSE))*E8 -> 1.5993012 | L8: =((J8*(1+I8))+3*(I8+K8))/4 -> 3.248676 | M8: 3 | N8: =VLOOKUP(A8,Demográfico!A$2:E$400,5,FALSE)*I8 -> 18525.799 | O8: =FLOOR(L8,1) -> 3 | P8: =L8-O8 -> 0.24867597 | Q8: =RANK(P8,P$2:P$400,0) -> 385 | R8: =O8+IF(Q8<Q$1,1,0) -> 3 | T8: =VLOOKUP(A8,Demográfico!A$2:E$400,5,FALSE)*(I8) -> 18525.799
A9: Colombo | B9: 232212 | C9: {=_xlfn.IFS(B9<20000, "P1",B9<40000, "P2",B9<70000, "P3",B9<100000, "P4",B9<200000,"M1",B9<500000,"M2",B9<1000000,"G1",B9>1000000,"G2")} -> M2 | D9: =VLOOKUP(C9,Controle!A$2:H$9,8,FALSE) -> 30.576514 | E9: =VLOOKUP(C9,Controle!A$16:H$23,8,FALSE) -> 10.582706 | F9: =VLOOKUP(A9,Educacional!A$2:P$405,16,FALSE) -> 66.409354 | G9: =VLOOKUP(A9,Demográfico!A$2:L$405,12,FALSE) -> 50.192481 | H9: =VLOOKUP(A9,Socioeconômico!A$2:M$405,13,FALSE) -> 37.235331 | I9: =(2*F9+G9+2*H9)/5/100 -> 0.5149637 | J9: =VLOOKUP(A9,Demográfico!A$2:E$400,5,FALSE)/(VLOOKUP(C9,Controle!A$2:G$9,7,FALSE))*D9 -> 3.9362804 | K9: =VLOOKUP(A9,Demográfico!A$2:E$400,5,FALSE)/(VLOOKUP(C9,Controle!A$16:G$24,7,FALSE))*E9 -> 1.3623692 | L9: =((J9*(1+I9))+3*(I9+K9))/4 -> 2.8988301 | M9: 2 | N9: =VLOOKUP(A9,Demográfico!A$2:E$400,5,FALSE)*I9 -> 17319.259 | O9: =FLOOR(L9,1) -> 2 | P9: =L9-O9 -> 0.89883013 | Q9: =RANK(P9,P$2:P$400,0) -> 8 | R9: =O9+IF(Q9<Q$1,1,0) -> 3 | T9: =VLOOKUP(A9,Demográfico!A$2:E$400,5,FALSE)*(I9) -> 17319.259
A10: Guarapuava | B10: 182093 | C10: {=_xlfn.IFS(B10<20000, "P1",B10<40000, "P2",B10<70000, "P3",B10<100000, "P4",B10<200000,"M1",B10<500000,"M2",B10<1000000,"G1",B10>1000000,"G2")} -> M1 | D10: =VLOOKUP(C10,Controle!A$2:H$9,8,FALSE) -> 30.793623 | E10: =VLOOKUP(C10,Controle!A$16:H$23,8,FALSE) -> 10.657849 | F10: =VLOOKUP(A10,Educacional!A$2:P$405,16,FALSE) -> 61.083403 | G10: =VLOOKUP(A10,Demográfico!A$2:L$405,12,FALSE) -> 55.600277 | H10: =VLOOKUP(A10,Socioeconômico!A$2:M$405,13,FALSE) -> 28.384009 | I10: =(2*F10+G10+2*H10)/5/100 -> 0.4690702 | J10: =VLOOKUP(A10,Demográfico!A$2:E$400,5,FALSE)/(VLOOKUP(C10,Controle!A$2:G$9,7,FALSE))*D10 -> 2.9908334 | K10: =VLOOKUP(A10,Demográfico!A$2:E$400,5,FALSE)/(VLOOKUP(C10,Controle!A$16:G$24,7,FALSE))*E10 -> 1.0351446 | L10: =((J10*(1+I10))+3*(I10+K10))/4 -> 2.2265971 | M10: 2 | N10: =VLOOKUP(A10,Demográfico!A$2:E$400,5,FALSE)*I10 -> 11986.62 | O10: =FLOOR(L10,1) -> 2 | P10: =L10-O10 -> 0.22659713 | Q10: =RANK(P10,P$2:P$400,0) -> 388 | R10: =O10+IF(Q10<Q$1,1,0) -> 2 | T10: =VLOOKUP(A10,Demográfico!A$2:E$400,5,FALSE)*(I10) -> 11986.62
A11: Araucária | B11: 151666 | C11: {=_xlfn.IFS(B11<20000, "P1",B11<40000, "P2",B11<70000, "P3",B11<100000, "P4",B11<200000,"M1",B11<500000,"M2",B11<1000000,"G1",B11>1000000,"G2")} -> M1 | D11: =VLOOKUP(C11,Controle!A$2:H$9,8,FALSE) -> 30.793623 | E11: =VLOOKUP(C11,Controle!A$16:H$23,8,FALSE) -> 10.657849 | F11: =VLOOKUP(A11,Educacional!A$2:P$405,16,FALSE) -> 48.892273 | G11: =VLOOKUP(A11,Demográfico!A$2:L$405,12,FALSE) -> 49.468609 | H11: =VLOOKUP(A11,Socioeconômico!A$2:M$405,13,FALSE) -> 16.192753 | I11: =(2*F11+G11+2*H11)/5/100 -> 0.35927732 | J11: =VLOOKUP(A11,Demográfico!A$2:E$400,5,FALSE)/(VLOOKUP(C11,Controle!A$2:G$9,7,FALSE))*D11 -> 2.6137314 | K11: =VLOOKUP(A11,Demográfico!A$2:E$400,5,FALSE)/(VLOOKUP(C11,Controle!A$16:G$24,7,FALSE))*E11 -> 0.90462738 | L11: =((J11*(1+I11))+3*(I11+K11))/4 -> 1.836125 | M11: 2 | N11: =VLOOKUP(A11,Demográfico!A$2:E$400,5,FALSE)*I11 -> 8023.3812 | O11: =FLOOR(L11,1) -> 1 | P11: =L11-O11 -> 0.83612498 | Q11: =RANK(P11,P$2:P$400,0) -> 15 | R11: =O11+IF(Q11<Q$1,1,0) -> 2 | T11: =VLOOKUP(A11,Demográfico!A$2:E$400,5,FALSE)*(I11) -> 8023.3812
A12: Toledo | B12: 150470 | C12: {=_xlfn.IFS(B12<20000, "P1",B12<40000, "P2",B12<70000, "P3",B12<100000, "P4",B12<200000,"M1",B12<500000,"M2",B12<1000000,"G1",B12>1000000,"G2")} -> M1 | D12: =VLOOKUP(C12,Controle!A$2:H$9,8,FALSE) -> 30.793623 | E12: =VLOOKUP(C12,Controle!A$16:H$23,8,FALSE) -> 10.657849 | F12: =VLOOKUP(A12,Educacional!A$2:P$405,16,FALSE) -> 51.77083 | G12: =VLOOKUP(A12,Demográfico!A$2:L$405,12,FALSE) -> 46.319074 | H12: =VLOOKUP(A12,Socioeconômico!A$2:M$405,13,FALSE) -> 7.3073309 | I12: =(2*F12+G12+2*H12)/5/100 -> 0.32895079 | J12: =VLOOKUP(A12,Demográfico!A$2:E$400,5,FALSE)/(VLOOKUP(C12,Controle!A$2:G$9,7,FALSE))*D12 -> 2.2892972 | K12: =VLOOKUP(A12,Demográfico!A$2:E$400,5,FALSE)/(VLOOKUP(C12,Controle!A$16:G$24,7,FALSE))*E12 -> 0.79233887 | L12: =((J12*(1+I12))+3*(I12+K12))/4 -> 1.6015581 | M12: 2 | N12: =VLOOKUP(A12,Demográfico!A$2:E$400,5,FALSE)*I12 -> 6434.2775 | O12: =FLOOR(L12,1) -> 1 | P12: =L12-O12 -> 0.60155809 | Q12: =RANK(P12,P$2:P$400,0) -> 72 | R12: =O12+IF(Q12<Q$1,1,0) -> 2 | T12: =VLOOKUP(A12,Demográfico!A$2:E$400,5,FALSE)*(I12) -> 6434.2775
A13: Fazenda Rio Grande | B13: 148873 | C13: {=_xlfn.IFS(B13<20000, "P1",B13<40000, "P2",B13<70000, "P3",B13<100000, "P4",B13<200000,"M1",B13<500000,"M2",B13<1000000,"G1",B13>1000000,"G2")} -> M1 | D13: =VLOOKUP(C13,Controle!A$2:H$9,8,FALSE) -> 30.793623 | E13: =VLOOKUP(C13,Controle!A$16:H$23,8,FALSE) -> 10.657849 | F13: =VLOOKUP(A13,Educacional!A$2:P$405,16,FALSE) -> 76.705674 | G13: =VLOOKUP(A13,Demográfico!A$2:L$405,12,FALSE) -> 60.165164 | H13: =VLOOKUP(A13,Socioeconômico!A$2:M$405,13,FALSE) -> 27.811608 | I13: =(2*F13+G13+2*H13)/5/100 -> 0.53839946 | J13: =VLOOKUP(A13,Demográfico!A$2:E$400,5,FALSE)/(VLOOKUP(C13,Controle!A$2:G$9,7,FALSE))*D13 -> 2.8812842 | K13: =VLOOKUP(A13,Demográfico!A$2:E$400,5,FALSE)/(VLOOKUP(C13,Controle!A$16:G$24,7,FALSE))*E13 -> 0.99722895 | L13: =((J13*(1+I13))+3*(I13+K13))/4 -> 2.2598628 | M13: 2 | N13: =VLOOKUP(A13,Demográfico!A$2:E$400,5,FALSE)*I13 -> 13254.318 | O13: =FLOOR(L13,1) -> 2 | P13: =L13-O13 -> 0.25986283 | Q13: =RANK(P13,P$2:P$400,0) -> 378 | R13: =O13+IF(Q13<Q$1,1,0) -> 2 | T13: =VLOOKUP(A13,Demográfico!A$2:E$400,5,FALSE)*(I13) -> 13254.318
A14: Paranaguá | B14: 145829 | C14: {=_xlfn.IFS(B14<20000, "P1",B14<40000, "P2",B14<70000, "P3",B14<100000, "P4",B14<200000,"M1",B14<500000,"M2",B14<1000000,"G1",B14>1000000,"G2")} -> M1 | D14: =VLOOKUP(C14,Controle!A$2:H$9,8,FALSE) -> 30.793623 | E14: =VLOOKUP(C14,Controle!A$16:H$23,8,FALSE) -> 10.657849 | F14: =VLOOKUP(A14,Educacional!A$2:P$405,16,FALSE) -> 65.086632 | G14: =VLOOKUP(A14,Demográfico!A$2:L$405,12,FALSE) -> 57.47484 | H14: =VLOOKUP(A14,Socioeconômico!A$2:M$405,13,FALSE) -> 27.509811 | I14: =(2*F14+G14+2*H14)/5/100 -> 0.48533545 | J14: =VLOOKUP(A14,Demográfico!A$2:E$400,5,FALSE)/(VLOOKUP(C14,Controle!A$2:G$9,7,FALSE))*D14 -> 2.4662613 | K14: =VLOOKUP(A14,Demográfico!A$2:E$400,5,FALSE)/(VLOOKUP(C14,Controle!A$16:G$24,7,FALSE))*E14 -> 0.85358715 | L14: =((J14*(1+I14))+3*(I14+K14))/4 -> 1.9199983 | M14: 2 | N14: =VLOOKUP(A14,Demográfico!A$2:E$400,5,FALSE)*I14 -> 10226.989 | O14: =FLOOR(L14,1) -> 1 | P14: =L14-O14 -> 0.9199983 | Q14: =RANK(P14,P$2:P$400,0) -> 5 | R14: =O14+IF(Q14<Q$1,1,0) -> 2 | T14: =VLOOKUP(A14,Demográfico!A$2:E$400,5,FALSE)*(I14) -> 10226.989
... A400: Nova Aliança do Ivaí | B400: 1323 | C400: {=_xlfn.IFS(B400<20000, "P1",B400<40000, "P2",B400<70000, "P3",B400<100000, "P4",B400<200000,"M1",B400<500000,"M2",B400<1000000,"G1",B400>1000000,"G2")} -> P1 | D400: =VLOOKUP(C400,Controle!A$2:H$9,8,FALSE) -> 38.874046 | E400: =VLOOKUP(C400,Controle!A$16:H$23,8,FALSE) -> 13.45453 | F400: =VLOOKUP(A400,Educacional!A$2:P$405,16,FALSE) -> 31.407634 | G400: =VLOOKUP(A400,Demográfico!A$2:L$405,12,FALSE) -> 34.543747 | H400: =VLOOKUP(A400,Socioeconômico!A$2:M$405,13,FALSE) -> 42.355356 | I400: =(2*F400+G400+2*H400)/5/100 -> 0.36413946 | J400: =VLOOKUP(A400,Demográfico!A$2:E$400,5,FALSE)/(VLOOKUP(C400,Controle!A$2:G$9,7,FALSE))*D400 -> 0.020598994 | K400: =VLOOKUP(A400,Demográfico!A$2:E$400,5,FALSE)/(VLOOKUP(C400,Controle!A$16:G$24,7,FALSE))*E400 -> 0.0071294295 | L400: =((J400*(1+I400))+3*(I400+K400))/4 -> 0.28547664 | M400: 0 | N400: =VLOOKUP(A400,Demográfico!A$2:E$400,5,FALSE)*I400 -> 64.088544 | O400: =FLOOR(L400,1) -> 0 | P400: =L400-O400 -> 0.28547664 | Q400: =RANK(P400,P$2:P$400,0) -> 369 | R400: =O400+IF(Q400<Q$1,1,0) -> 0 | T400: =VLOOKUP(A400,Demográfico!A$2:E$400,5,FALSE)*(I400) -> 64.088544
N401: =SUM(N2:N400)/Demográfico!E405 -> 0.43812895
T402: =SUM(T2:T400)/Controle!C10 -> 0.43812895

Sheet Controle
A1: Faixa | B1: Recorte Populacional Total | C1: População Alvo | D1: Proporção | E1: Municípios | F1: Contemplado | G1: Prop Ajustado | H1: Ponderação Pop | I1: Total | J1: Proporção
A2: G2 | B2: Acima de 1 milhão de habitantes | C2: =SUMIF(Demográfico!M$2:M$400,Controle!A2,Demográfico!E$2:E$400) -> 202402 | D2: =C2/C$10 -> 0.13519027 | E2: =COUNTIF(CI!C$2:C$400,Controle!A2) -> 1 | F2: Sim | G2: =IF(F2=O$2,SUMIF(Demográfico!M$2:M$400,Controle!A2,Demográfico!E$2:E$400),0) -> 202402 | H2: =IF(F2=O$2,D2*F$10,0) -> 23.689077 | I2: =SUMIF(CI!C$2:C$400,Controle!A2,CI!R$2:R$400) -> 14 | J2: =I2/F$11 -> 0.055555556 | O2: Sim
A3: G1 | B3: Entre 500 mil até 1 milhão habitantes | C3: =SUMIF(Demográfico!M$2:M$400,Controle!A3,Demográfico!E$2:E$400) -> 66820 | D3: =C3/C$10 -> 0.044631049 | E3: =COUNTIF(CI!C$2:C$400,Controle!A3) -> 1 | F3: Sim | G3: =IF(F3=O$2,SUMIF(Demográfico!M$2:M$400,Controle!A3,Demográfico!E$2:E$400),0) -> 66820 | H3: =IF(F3=O$2,D3*F$10,0) -> 7.8205952 | I3: =SUMIF(CI!C$2:C$400,Controle!A3,CI!R$2:R$400) -> 5 | J3: =I3/F$11 -> 0.01984127 | O3: Não
A4: M2 | B4: Entre 200 até 500 mil habitantes | C4: =SUMIF(Demográfico!M$2:M$400,Controle!A4,Demográfico!E$2:E$400) -> 261249 | D4: =C4/C$10 -> 0.17449591 | E4: =COUNTIF(CI!C$2:C$400,Controle!A4) -> 6 | F4: Sim | G4: =IF(F4=O$2,SUMIF(Demográfico!M$2:M$400,Controle!A4,Demográfico!E$2:E$400),0) -> 261249 | H4: =IF(F4=O$2,D4*F$10,0) -> 30.576514 | I4: =SUMIF(CI!C$2:C$400,Controle!A4,CI!R$2:R$400) -> 21 | J4: =I4/F$11 -> 0.083333333
A5: M1 | B5: Entre 100 até 200 mil habitantes | C5: =SUMIF(Demográfico!M$2:M$400,Controle!A5,Demográfico!E$2:E$400) -> 263104 | D5: =C5/C$10 -> 0.17573492 | E5: =COUNTIF(CI!C$2:C$400,Controle!A5) -> 14 | F5: Sim | G5: =IF(F5=O$2,SUMIF(Demográfico!M$2:M$400,Controle!A5,Demográfico!E$2:E$400),0) -> 263104 | H5: =IF(F5=O$2,D5*F$10,0) -> 30.793623 | I5: =SUMIF(CI!C$2:C$400,Controle!A5,CI!R$2:R$400) -> 24 | J5: =I5/F$11 -> 0.095238095
A6: P4 | B6: Entre 70 a 100 mil habitantes | C6: =SUMIF(Demográfico!M$2:M$400,Controle!A6,Demográfico!E$2:E$400) -> 90999 | D6: =C6/C$10 -> 0.060780916 | E6: =COUNTIF(CI!C$2:C$400,Controle!A6) -> 8 | F6: Sim | G6: =IF(F6=O$2,SUMIF(Demográfico!M$2:M$400,Controle!A6,Demográfico!E$2:E$400),0) -> 90999 | H6: =IF(F6=O$2,D6*F$10,0) -> 10.650499 | I6: =SUMIF(CI!C$2:C$400,Controle!A6,CI!R$2:R$400) -> 8 | J6: =I6/F$11 -> 0.031746032 | O6: =SUM(G2:G9) -> 1497164
A7: P3 | B7: Entre 40 a 70 mil habitantes | C7: =SUMIF(Demográfico!M$2:M$400,Controle!A7,Demográfico!E$2:E$400) -> 108749 | D7: =C7/C$10 -> 0.072636665 | E7: =COUNTIF(CI!C$2:C$400,Controle!A7) -> 17 | F7: Sim | G7: =IF(F7=O$2,SUMIF(Demográfico!M$2:M$400,Controle!A7,Demográfico!E$2:E$400),0) -> 108749 | H7: =IF(F7=O$2,D7*F$10,0) -> 12.727954 | I7: =SUMIF(CI!C$2:C$400,Controle!A7,CI!R$2:R$400) -> 17 | J7: =I7/F$11 -> 0.067460317
A8: P2 | B8: Entre 20 a 40 mil habitantes | C8: =SUMIF(Demográfico!M$2:M$400,Controle!A8,Demográfico!E$2:E$400) -> 171697 | D8: =C8/C$10 -> 0.11468149 | E8: =COUNTIF(CI!C$2:C$400,Controle!A8) -> 45 | F8: Sim | G8: =IF(F8=O$2,SUMIF(Demográfico!M$2:M$400,Controle!A8,Demográfico!E$2:E$400),0) -> 171697 | H8: =IF(F8=O$2,D8*F$10,0) -> 20.095372 | I8: =SUMIF(CI!C$2:C$400,Controle!A8,CI!R$2:R$400) -> 43 | J8: =I8/F$11 -> 0.17063492
A9: P1 | B9: Até 20 mil habitantes | C9: =SUMIF(Demográfico!M$2:M$400,Controle!A9,Demográfico!E$2:E$400) -> 332144 | D9: =C9/C$10 -> 0.22184878 | E9: =COUNTIF(CI!C$2:C$400,Controle!A9) -> 307 | F9: Sim | G9: =IF(F9=O$2,SUMIF(Demográfico!M$2:M$400,Controle!A9,Demográfico!E$2:E$400),0) -> 332144 | H9: =IF(F9=O$2,D9*F$10,0) -> 38.874046 | I9: =SUMIF(CI!C$2:C$400,Controle!A9,CI!R$2:R$400) -> 119 | J9: =I9/F$11 -> 0.47222222
A10: TOTAL | C10: =SUM(G2:G9) -> 1497164 | E10: SIMULAÇÃO | F10: =F11/(1+C11) -> 175.22768
A11: PCM Ponderado | C11: =CI!T402 -> 0.43812895 | D11: Creches a Serem Construídas | F11: 252
A15: Faixa | B15: Recorte Populacional Total | C15: População Alvo | D15: Proporção | E15: Municípios | F15: Contemplado | G15: Prop Ajustado | H15: Ponderação Pop | I15: Total | J15: Proporção
A16: G2 | B16: Acima de 1 milhão de habitantes | C16: =SUMIF(Demográfico!M$2:M$400,Controle!A16,Demográfico!E$2:E$400) -> 202402 | D16: =C16/C$10 -> 0.13519027 | E16: =COUNTIF(CI!C$2:C$400,Controle!A16) -> 1 | F16: Sim | G16: =IF(F16=O$2,SUMIF(Demográfico!M$2:M$400,Controle!A16,Demográfico!E$2:E$400),0) -> 202402 | H16: =IF(F16=O$2,D16*F$24,0) -> 8.1989249 | I16: =SUMIF(CI!C$2:C$400,Controle!A16,CI!R$2:R$400) -> 14 | J16: =I16/F$11 -> 0.055555556
A17: G1 | B17: Entre 500 mil até 1 milhão habitantes | C17: =SUMIF(Demográfico!M$2:M$400,Controle!A17,Demográfico!E$2:E$400) -> 66820 | D17: =C17/C$10 -> 0.044631049 | E17: =COUNTIF(CI!C$2:C$400,Controle!A17) -> 1 | F17: Sim | G17: =IF(F17=O$2,SUMIF(Demográfico!M$2:M$400,Controle!A17,Demográfico!E$2:E$400),0) -> 66820 | H17: =IF(F17=O$2,D17*F$24,0) -> 2.7067527 | I17: =SUMIF(CI!C$2:C$400,Controle!A17,CI!R$2:R$400) -> 5 | J17: =I17/F$11 -> 0.01984127
A18: M2 | B18: Entre 200 até 500 mil habitantes | C18: =SUMIF(Demográfico!M$2:M$400,Controle!A18,Demográfico!E$2:E$400) -> 261249 | D18: =C18/C$10 -> 0.17449591 | E18: =COUNTIF(CI!C$2:C$400,Controle!A18) -> 6 | F18: Sim | G18: =IF(F18=O$2,SUMIF(Demográfico!M$2:M$400,Controle!A18,Demográfico!E$2:E$400),0) -> 261249 | H18: =IF(F18=O$2,D18*F$24,0) -> 10.582706 | I18: =SUMIF(CI!C$2:C$400,Controle!A18,CI!R$2:R$400) -> 21 | J18: =I18/F$11 -> 0.083333333
A19: M1 | B19: Entre 100 até 200 mil habitantes | C19: =SUMIF(Demográfico!M$2:M$400,Controle!A19,Demográfico!E$2:E$400) -> 263104 | D19: =C19/C$10 -> 0.17573492 | E19: =COUNTIF(CI!C$2:C$400,Controle!A19) -> 14 | F19: Sim | G19: =IF(F19=O$2,SUMIF(Demográfico!M$2:M$400,Controle!A19,Demográfico!E$2:E$400),0) -> 263104 | H19: =IF(F19=O$2,D19*F$24,0) -> 10.657849 | I19: =SUMIF(CI!C$2:C$400,Controle!A19,CI!R$2:R$400) -> 24 | J19: =I19/F$11 -> 0.095238095
A20: P4 | B20: Entre 70 a 100 mil habitantes | C20: =SUMIF(Demográfico!M$2:M$400,Controle!A20,Demográfico!E$2:E$400) -> 90999 | D20: =C20/C$10 -> 0.060780916 | E20: =COUNTIF(CI!C$2:C$400,Controle!A20) -> 8 | F20: Sim | G20: =IF(F20=O$2,SUMIF(Demográfico!M$2:M$400,Controle!A20,Demográfico!E$2:E$400),0) -> 90999 | H20: =IF(F20=O$2,D20*F$24,0) -> 3.6861986 | I20: =SUMIF(CI!C$2:C$400,Controle!A20,CI!R$2:R$400) -> 8 | J20: =I20/F$11 -> 0.031746032
A21: P3 | B21: Entre 40 a 70 mil habitantes | C21: =SUMIF(Demográfico!M$2:M$400,Controle!A21,Demográfico!E$2:E$400) -> 108749 | D21: =C21/C$10 -> 0.072636665 | E21: =COUNTIF(CI!C$2:C$400,Controle!A21) -> 17 | F21: Sim | G21: =IF(F21=O$2,SUMIF(Demográfico!M$2:M$400,Controle!A21,Demográfico!E$2:E$400),0) -> 108749 | H21: =IF(F21=O$2,D21*F$24,0) -> 4.4052178 | I21: =SUMIF(CI!C$2:C$400,Controle!A21,CI!R$2:R$400) -> 17 | J21: =I21/F$11 -> 0.067460317
A22: P2 | B22: Entre 20 a 40 mil habitantes | C22: =SUMIF(Demográfico!M$2:M$400,Controle!A22,Demográfico!E$2:E$400) -> 171697 | D22: =C22/C$10 -> 0.11468149 | E22: =COUNTIF(CI!C$2:C$400,Controle!A22) -> 45 | F22: Sim | G22: =IF(F22=O$2,SUMIF(Demográfico!M$2:M$400,Controle!A22,Demográfico!E$2:E$400),0) -> 171697 | H22: =IF(F22=O$2,D22*F$24,0) -> 6.955123 | I22: =SUMIF(CI!C$2:C$400,Controle!A22,CI!R$2:R$400) -> 43 | J22: =I22/F$11 -> 0.17063492
A23: P1 | B23: Até 20 mil habitantes | C23: =SUMIF(Demográfico!M$2:M$400,Controle!A23,Demográfico!E$2:E$400) -> 332144 | D23: =C23/C$10 -> 0.22184878 | E23: =COUNTIF(CI!C$2:C$400,Controle!A23) -> 307 | F23: Sim | G23: =IF(F23=O$2,SUMIF(Demográfico!M$2:M$400,Controle!A23,Demográfico!E$2:E$400),0) -> 332144 | H23: =IF(F23=O$2,D23*F$24,0) -> 13.45453 | I23: =SUMIF(CI!C$2:C$400,Controle!A23,CI!R$2:R$400) -> 119 | J23: =I23/F$11 -> 0.47222222
A24: TOTAL | C24: =SUM(C16:C23) -> 1497164 | E24: SIMULAÇÃO | F24: =F25-C25 -> 60.647302
A25: PCM Soma | C25: =SUM(CI!I2:I400) -> 191.3527 | D25: Creches a Serem Construídas | F25: =F11 -> 252

Sheet Educacional
B1: Código [-] | C1: Matriculas Creches | D1: População 0 a 4 | E1: Proporção | F1: Creche_Normalizado | G1: Matriculas Pré-Escola e Fundamental | H1: População 5 a 14 | I1: Proporção | J1: Matrícula_Normalizado | K1: Oferta Privado | L1: Oferta Total | M1: Total Oferta | N1: Privado_Normalizado | O1: FATOR EDUCAÇÃO
A2: Curitiba | B2: 4106902 | C2: 17725 | D2: 85003 | E2: 0.20852205 | F2: 67.953453 | G2: 233206 | H2: 202402 | I2: 1.1521922 | J2: 72.220046 | K2: 379 | L2: 604 | M2: 0.62748344 | N2: 37.251656 | O2: =(2*F2+J2+N2)/4 -> 61.344652 | P2: =(O2-O$402)/(O$403-O$402)*100 -> 56.511036
A3: Foz do Iguaçu | B3: 4108304 | C3: 4900 | D3: 18300 | E3: 0.26775956 | F3: 58.849583 | G3: 43678 | H3: 39481 | I3: 1.1063043 | J3: 75.341642 | K3: 29 | L3: 73 | M3: 0.39726027 | N3: 60.273973 | O3: =(2*F3+J3+N3)/4 -> 63.328695 | P3: =(O3-O$402)/(O$403-O$402)*100 -> 59.854018
A4: Maringá | B4: 4115200 | C4: 6614 | D4: 21680 | E4: 0.3050738 | F4: 53.114974 | G4: 53527 | H4: 45546 | I4: 1.1752294 | J4: 70.652899 | K4: 63 | L4: 125 | M4: 0.504 | N4: 49.6 | O4: =(2*F4+J4+N4)/4 -> 56.620712 | P4: =(O4-O$402)/(O$403-O$402)*100 -> 48.551508
A5: Cascavel | B5: 4104808 | C5: 5285 | D5: 23119 | E5: 0.22859985 | F5: 64.867812 | G5: 50655 | H5: 45120 | I5: 1.1226729 | J5: 74.228144 | K5: 46 | L5: 102 | M5: 0.45098039 | N5: 54.901961 | O5: =(2*F5+J5+N5)/4 -> 64.716432 | P5: =(O5-O$402)/(O$403-O$402)*100 -> 62.192264
A6: Londrina | B6: 4113700 | C6: 2282 | D6: 30194 | E6: 0.075577929 | F6: 88.384866 | G6: 77042 | H6: 66820 | I6: 1.1529782 | J6: 72.166579 | K6: 152 | L6: 187 | M6: 0.81283422 | N6: 18.716578 | O6: =(2*F6+J6+N6)/4 -> 66.913222 | P6: =(O6-O$402)/(O$403-O$402)*100 -> 65.89371
A7: Ponta Grossa | B7: 4119905 | C7: 4698 | D7: 22756 | E7: 0.20645105 | F7: 68.271734 | G7: 54861 | H7: 50454 | I7: 1.0873469 | J7: 76.63125 | K7: 37 | L7: 105 | M7: 0.35238095 | N7: 64.761905 | O7: =(2*F7+J7+N7)/4 -> 69.484156 | P7: =(O7-O$402)/(O$403-O$402)*100 -> 70.225565
A8: São José dos Pinhais | B8: 4125506 | C8: 3447 | D8: 21137 | E8: 0.16307896 | F8: 74.937339 | G8: 52037 | H8: 47016 | I8: 1.1067934 | J8: 75.308368 | K8: 37 | L8: 82 | M8: 0.45121951 | N8: 54.878049 | O8: =(2*F8+J8+N8)/4 -> 70.015273 | P8: =(O8-O$402)/(O$403-O$402)*100 -> 71.120463
A9: Colombo | B9: 4105805 | C9: 3929 | D9: 14801 | E9: 0.26545504 | F9: 59.203752 | G9: 37968 | H9: 33632 | I9: 1.1289248 | J9: 73.802844 | K9: 14 | L9: 60 | M9: 0.23333333 | N9: 76.666667 | O9: =(2*F9+J9+N9)/4 -> 67.219254 | P9: =(O9-O$402)/(O$403-O$402)*100 -> 66.409354
A10: Araucária | B10: 4101804 | C10: 3972 | D10: 10075 | E10: 0.39424318 | F10: 39.411049 | G10: 25488 | H10: 22332 | I10: 1.1413219 | J10: 72.959516 | K10: 12 | L10: 49 | M10: 0.24489796 | N10: 75.510204 | O10: =(2*F10+J10+N10)/4 -> 56.822954 | P10: =(O10-O$402)/(O$403-O$402)*100 -> 48.892273
A11: Guarapuava | B11: 4109401 | C11: 2947 | D11: 12791 | E11: 0.23039637 | F11: 64.591715 | G11: 29194 | H11: 25554 | I11: 1.1424435 | J11: 72.883218 | K11: 22 | L11: 48 | M11: 0.45833333 | N11: 54.166667 | O11: =(2*F11+J11+N11)/4 -> 64.058329 | P11: =(O11-O$402)/(O$403-O$402)*100 -> 61.083403
A12: Fazenda Rio Grande | B12: 4107652 | C12: 1781 | D12: 11090 | E12: 0.16059513 | F12: 75.319064 | G12: 26388 | H12: 24618 | I12: 1.0718986 | J12: 77.682144 | K12: 7 | L12: 20 | M12: 0.35 | N12: 65 | O12: =(2*F12+J12+N12)/4 -> 73.330068 | P12: =(O12-O$402)/(O$403-O$402)*100 -> 76.705674
A13: Toledo | B13: 4127700 | C13: 3483 | D13: 9412 | E13: 0.3700595 | F13: 43.127698 | G13: 21824 | H13: 19560 | I13: 1.1157464 | J13: 74.699326 | K13: 11 | L13: 41 | M13: 0.26829268 | N13: 73.170732 | O13: =(2*F13+J13+N13)/4 -> 58.531364 | P13: =(O13-O$402)/(O$403-O$402)*100 -> 51.77083
... A400: Sulina | B400: 4126652 | C400: 0 | D400: 209 | E400: 0 | F400: 100 | G400: 441 | H400: 415 | I400: 1.0626506 | J400: 78.311254 | K400: 1 | L400: 1 | M400: 1 | N400: 0 | O400: =(2*F400+J400+N400)/4 -> 69.577814 | P400: =(O400-O$402)/(O$403-O$402)*100 -> 70.383372
A402: Quartil Minimo | E402: =QUARTILE(E1:E400,0) -> 0 | I402: =QUARTILE(I1:I400,0) -> 0.74382315 | J402: =QUARTILE(J1:J400,0) -> 0 | K402: =QUARTILE(K1:K400,0) -> 0 | L402: =QUARTILE(L1:L400,0) -> 1 | M402: =QUARTILE(M1:M400,0) -> 0 | N402: =QUARTILE(N1:N400,0) -> 0 | O402: =QUARTILE(O1:O400,0) -> 27.805636
A403: Quartil Máximo | E403: =QUARTILE(E2:E400,4) -> 0.65068493 | I403: =QUARTILE(I2:I400,4) -> 2.2138365 | J403: =QUARTILE(J2:J400,4) -> 100 | K403: =QUARTILE(K2:K400,4) -> 379 | L403: =QUARTILE(L2:L400,4) -> 604 | M403: =QUARTILE(M2:M400,4) -> 1 | N403: =QUARTILE(N2:N400,4) -> 100 | O403: =QUARTILE(O2:O400,4) -> 87.155133

Sheet Demográfico
B1: Código [-] | C1: Mortalidade Infantil | D1: MI_Normalizado | E1: População 0 a 4 | F1: População Total | G1: Proporção | H1: Proporção_Normalizado | I1: Taxa de Natalidade | J1: Natalidade_Normalizado | K1: FATOR DEMOGRÁFICO
A2: Curitiba | B2: 4106902 | C2: 7.1 | D2: 12.778978 | E2: 202402 | F2: 1773718 | G2: 0.11411171 | H2: 66.323434 | I2: 10.37 | J2: 55.573419 | K2: =(D2+H2+J2)/3 -> 44.891944 | L2: =(K2-K$401)/(K$402-K$401)*100 -> 29.902254 | M2: =VLOOKUP(A2,CI!A$2:C$400,3,FALSE) -> G2
A3: Foz do Iguaçu | B3: 4108304 | C3: 9.14 | D3: 16.450684 | E3: 39481 | F3: 285415 | G3: 0.1383284 | H3: 80.398534 | I3: 14.08 | J3: 75.45552 | K3: =(D3+H3+J3)/3 -> 57.434913 | L3: =(K3-K$401)/(K$402-K$401)*100 -> 53.393821 | M3: =VLOOKUP(A3,CI!A$2:C$400,3,FALSE) -> M2
A4: Maringá | B4: 4115200 | C4: 7.29 | D4: 13.12095 | E4: 45546 | F4: 409657 | G4: 0.11118082 | H4: 64.619953 | I4: 11.36 | J4: 60.878885 | K4: =(D4+H4+J4)/3 -> 46.206596 | L4: =(K4-K$401)/(K$402-K$401)*100 -> 32.36445 | M4: =VLOOKUP(A4,CI!A$2:C$400,3,FALSE) -> M2
A5: Cascavel | B5: 4104808 | C5: 7.09 | D5: 12.760979 | E5: 45120 | F5: 348051 | G5: 0.12963617 | H5: 75.346483 | I5: 13.61 | J5: 72.936763 | K5: =(D5+H5+J5)/3 -> 53.681408 | L5: =(K5-K$401)/(K$402-K$401)*100 -> 46.363931 | M5: =VLOOKUP(A5,CI!A$2:C$400,3,FALSE) -> M2
A6: Londrina | B6: 4113700 | C6: 11.84 | D6: 21.310295 | E6: 66820 | F6: 555965 | G6: 0.12018742 | H6: 69.854727 | I6: 11 | J6: 58.949625 | K6: =(D6+H6+J6)/3 -> 50.038216 | L6: =(K6-K$401)/(K$402-K$401)*100 -> 39.540641 | M6: =VLOOKUP(A6,CI!A$2:C$400,3,FALSE) -> G1
A7: Ponta Grossa | B7: 4119905 | C7: 9.08 | D7: 16.342693 | E7: 50454 | F7: 358371 | G7: 0.14078706 | H7: 81.827545 | I7: 13.01 | J7: 69.721329 | K7: =(D7+H7+J7)/3 -> 55.963856 | L7: =(K7-K$401)/(K$402-K$401)*100 -> 50.638697 | M7: =VLOOKUP(A7,CI!A$2:C$400,3,FALSE) -> M2
A8: São José dos Pinhais | B8: 4125506 | C8: 9.19 | D8: 16.540677 | E8: 47016 | F8: 329628 | G8: 0.14263351 | H8: 82.900731 | I8: 12.92 | J8: 69.239014 | K8: =(D8+H8+J8)/3 -> 56.226807 | L8: =(K8-K$401)/(K$402-K$401)*100 -> 51.131176 | M8: =VLOOKUP(A8,CI!A$2:C$400,3,FALSE) -> M2
A9: Colombo | B9: 4105805 | C9: 8.21 | D9: 14.776818 | E9: 33632 | F9: 232212 | G9: 0.14483317 | H9: 84.179204 | I9: 12.73 | J9: 68.220793 | K9: =(D9+H9+J9)/3 -> 55.725605 | L9: =(K9-K$401)/(K$402-K$401)*100 -> 50.192481 | M9: =VLOOKUP(A9,CI!A$2:C$400,3,FALSE) -> M2
A10: Araucária | B10: 4101804 | C10: 6.4 | D10: 11.519078 | E10: 22332 | F10: 151666 | G10: 0.1472446 | H10: 85.580765 | I10: 12.86 | J10: 68.917471 | K10: =(D10+H10+J10)/3 -> 55.339105 | L10: =(K10-K$401)/(K$402-K$401)*100 -> 49.468609 | M10: =VLOOKUP(A10,CI!A$2:C$400,3,FALSE) -> M1
A11: Guarapuava | B11: 4109401 | C11: 9.89 | D11: 17.800576 | E11: 25554 | F11: 182093 | G11: 0.14033488 | H11: 81.564733 | I11: 14.27 | J11: 76.473741 | K11: =(D11+H11+J11)/3 -> 58.613017 | L11: =(K11-K$401)/(K$402-K$401)*100 -> 55.600277 | M11: =VLOOKUP(A11,CI!A$2:C$400,3,FALSE) -> M1
A12: Fazenda Rio Grande | B12: 4107652 | C12: 9.92 | D12: 17.854572 | E12: 24618 | F12: 148873 | G12: 0.16536242 | H12: 96.111113 | I12: 12.91 | J12: 69.185423 | K12: =(D12+H12+J12)/3 -> 61.050369 | L12: =(K12-K$401)/(K$402-K$401)*100 -> 60.165164 | M12: =VLOOKUP(A12,CI!A$2:C$400,3,FALSE) -> M1
A13: Toledo | B13: 4127700 | C13: 7.59 | D13: 13.660907 | E13: 19560 | F13: 150470 | G13: 0.12999269 | H13: 75.553695 | I13: 13.39 | J13: 71.757771 | K13: =(D13+H13+J13)/3 -> 53.657458 | L13: =(K13-K$401)/(K$402-K$401)*100 -> 46.319074 | M13: =VLOOKUP(A13,CI!A$2:C$400,3,FALSE) -> M1
... A400: Sulina | B400: 4126652 | C400: 0 | D400: 0 | E400: 415 | F400: 3440 | G400: 0.12063953 | H400: 70.117502 | I400: 12.79 | J400: 68.542337 | K400: =(D400+H400+J400)/3 -> 46.219946 | L400: =(K400-K$401)/(K$402-K$401)*100 -> 32.389453 | M400: =VLOOKUP(A400,CI!A$2:C$400,3,FALSE) -> P1
C401: 0 | D401: 0 | E401: 176 | F401: 1323 | G401: 0.10421412 | H401: 60.570807 | I401: 3.56 | J401: 19.078242 | K401: =QUARTILE(K2:K400,0) -> 28.926085 | M401: =VLOOKUP(A401,CI!A$2:C$400,3,FALSE) -> #N/A
C402: 55.56 | D402: 100 | E402: 202402 | F402: 1773718 | G402: 0.17205338 | H402: 100 | I402: 18.66 | J402: 100 | K402: =QUARTILE(K2:K400,4) -> 82.319581 | M402: =VLOOKUP(A402,CI!A$2:C$400,3,FALSE) -> #N/A
E405: =SUM(E$2:E$400) -> 1497164

Sheet Socioeconômico
B1: Código | C1: [-] | D1: Proporção | E1: Desnutrição_Normalizado | F1: CADUnico | G1: População 5 a 14 | H1: Proporção | I1: CADUnico_Normalizado | J1: IPDM-R | K1: Oferta Total | L1: FATOR SOCIOECONÔMICO
A2: Curitiba | B2: 410690 | C2: 2 | D2: 0.039521186 | E2: 3.9521186 | F2: 23579 | G2: 185447 | H2: 0.12714684 | I2: 16.666237 | J2: 0.83316572 | K2: 0 | L2: =(K2+I2+E2)/3 -> 6.8727851 | M2: =(L2-L$402)/(L$403-L$402)*100 -> 0
A3: Foz do Iguaçu | B3: 410830 | C3: 4 | D3: 0.038194444 | E3: 3.8194444 | F3: 9447 | G3: 38190 | H3: 0.24736842 | I3: 37.344134 | J3: 0.59942021 | K3: 38.905252 | L3: =(K3+I3+E3)/3 -> 26.68961 | M3: =(L3-L$402)/(L$403-L$402)*100 -> 30.757393
A4: Maringá | B4: 411520 | C4: 0 | D4: 0.03707518 | E4: 3.707518 | F4: 5145 | G4: 44828 | H4: 0.11477202 | I4: 14.537789 | J4: 0.67167541 | K4: 26.878896 | L4: =(K4+I4+E4)/3 -> 15.041401 | M4: =(L4-L$402)/(L$403-L$402)*100 -> 12.678385
A5: Cascavel | B5: 410480 | C5: 8 | D5: 0.024749868 | E5: 2.4749868 | F5: 6125 | G5: 46503 | H5: 0.13171193 | I5: 17.451425 | J5: 0.6886966 | K5: 24.045842 | L5: =(K5+I5+E5)/3 -> 14.657418 | M5: =(L5-L$402)/(L$403-L$402)*100 -> 12.08241
A6: Londrina | B6: 411370 | C6: 0 | D6: 0.048085901 | E6: 4.8085901 | F6: 12581 | G6: 63953 | H6: 0.19672259 | I6: 28.633142 | J6: 0.62865828 | K6: 34.038786 | L6: =(K6+I6+E6)/3 -> 22.493506 | M6: =(L6-L$402)/(L$403-L$402)*100 -> 24.244683
A7: Ponta Grossa | B7: 411990 | C7: 5 | D7: 0.021359223 | E7: 2.1359223 | F7: 8465 | G7: 48349 | H7: 0.17508118 | I7: 24.910858 | J7: 0.59499454 | K7: 39.641873 | L7: =(K7+I7+E7)/3 -> 22.229551 | M7: =(L7-L$402)/(L$403-L$402)*100 -> 23.835003
A8: São José dos Pinhais | B8: 412550 | C8: 6 | D8: 0.065654493 | E8: 6.5654493 | F8: 6404 | G8: 45199 | H8: 0.14168455 | I8: 19.166697 | J8: 0.69416041 | K8: 23.136431 | L8: =(K8+I8+E8)/3 -> 16.289526 | M8: =(L8-L$402)/(L$403-L$402)*100 -> 14.61558
A9: Colombo | B9: 410580 | C9: 5 | D9: 0.056998557 | E9: 5.6998557 | F9: 6643 | G9: 31809 | H9: 0.20884027 | I9: 30.71736 | J9: 0.49567605 | K9: 56.172718 | L9: =(K9+I9+E9)/3 -> 30.863311 | M9: =(L9-L$402)/(L$403-L$402)*100 -> 37.235331
A10: Araucária | B10: 410180 | C10: 4 | D10: 0.034263959 | E10: 3.4263959 | F10: 3496 | G10: 21525 | H10: 0.1624158 | I10: 22.732434 | J10: 0.67840839 | K10: 25.75824 | L10: =(K10+I10+E10)/3 -> 17.30569 | M10: =(L10-L$402)/(L$403-L$402)*100 -> 16.192753
A11: Guarapuava | B11: 410940 | C11: 1 | D11: 0.06445993 | E11: 6.445993 | F11: 6158 | G11: 25977 | H11: 0.23705586 | I11: 35.570392 | J11: 0.63210581 | K11: 33.46497 | L11: =(K11+I11+E11)/3 -> 25.160452 | M11: =(L11-L$402)/(L$403-L$402)*100 -> 28.384009
A12: Fazenda Rio Grande | B12: 410765 | C12: 2 | D12: 0.054669704 | E12: 5.4669704 | F12: 3274 | G12: 23587 | H12: 0.13880527 | I12: 18.671467 | J12: 0.53134107 | K12: 50.236533 | L12: =(K12+I12+E12)/3 -> 24.791657 | M12: =(L12-L$402)/(L$403-L$402)*100 -> 27.811608
A13: Toledo | B13: 412770 | C13: 0 | D13: 0.035890218 | E13: 3.5890218 | F13: 1500 | G13: 19622 | H13: 0.076444807 | I13: 7.9455774 | J13: 0.69373054 | K13: 23.20798 | L13: =(K13+I13+E13)/3 -> 11.58086 | M13: =(L13-L$402)/(L$403-L$402)*100 -> 7.3073309
... A400: Sulina | B400: 412665 | C400: 2 | D400: 0 | E400: 0 | F400: 75 | G400: 412 | H400: 0.18203883 | I400: 26.107562 | J400: 0.45482776 | K400: 62.97162 | L400: =(K400+I400+E400)/3 -> 29.693061 | M400: =(L400-L$402)/(L$403-L$402)*100 -> 35.419003
D402: =QUARTILE(D2:D400,0) -> 0 | E402: =QUARTILE(E2:E400,0) -> 0 | F402: =QUARTILE(F2:F400,0) -> 17 | G402: =QUARTILE(G2:G400,0) -> 164 | H402: =QUARTILE(H2:H400,0) -> 0.03024911 | I402: =QUARTILE(I2:I400,0) -> 0 | J402: =QUARTILE(J2:J400,0) -> 0.23235863 | K402: =QUARTILE(K2:K400,0) -> 0 | ... O402: =QUARTILE(O2:O400,0) -> #NUM!
D403: =QUARTILE(D2:D400,4) -> 1 | E403: =QUARTILE(E2:E400,4) -> 100 | F403: =QUARTILE(F2:F400,4) -> 23579 | G403: =QUARTILE(G2:G400,4) -> 185447 | H403: =QUARTILE(H2:H400,4) -> 0.61165049 | I403: =QUARTILE(I2:I400,4) -> 100 | J403: =QUARTILE(J2:J400,4) -> 0.83316572 | K403: =QUARTILE(K2:K400,4) -> 100 | ... O403: =QUARTILE(O2:O400,4) -> #NUM!

Sheet Municipios
A1: MUNICÍPIO | B1: Coluna1 | C1: Coluna2 | D1: Coluna3 | E1: Coluna4 | F1: Coluna5 | G1: Coluna6 | H1: Coluna7 | L1: Guaraqueçaba
A2: CASCAVEL | B2: 7 | C2: R | D2: =VLOOKUP(Municipios!A2,CI!A$2:R$400,18,FALSE) -> 4 | E2: =B2-D2 -> 3 | F2: =VLOOKUP(Municipios!A2,CI!A$2:R$400,9,FALSE) -> 0.38982656 | G2: =VLOOKUP(A2,[1]CI!$A$2:$P$400,9,FALSE) -> 1.7723021 | H2: =VLOOKUP(A2,[1]CI!$A$2:$Q$400,17,FALSE) -> 332 | L2: Diamante do Sul
A3: ASTORGA | B3: 1 | C3: SD | D3: =VLOOKUP(Municipios!A3,CI!A$2:R$400,18,FALSE) -> 1 | E3: =B3-D3 -> 0 | F3: =VLOOKUP(Municipios!A3,CI!A$2:R$400,9,FALSE) -> 0.44903439 | G3: =VLOOKUP(A3,[1]CI!$A$2:$P$400,9,FALSE) -> 0.12479175 | H3: =VLOOKUP(A3,[1]CI!$A$2:$Q$400,17,FALSE) -> 246 | L3: Doutor Ulysses
A4: ATALAIA | B4: 1 | C4: SD | D4: =VLOOKUP(Municipios!A4,CI!A$2:R$400,18,FALSE) -> 0 | E4: =B4-D4 -> 1 | F4: =VLOOKUP(Municipios!A4,CI!A$2:R$400,9,FALSE) -> 0.28051616 | G4: =VLOOKUP(A4,[1]CI!$A$2:$P$400,9,FALSE) -> 0.016536773 | H4: =VLOOKUP(A4,[1]CI!$A$2:$Q$400,17,FALSE) -> 393 | L4: Cerro Azul | P4: 14
A5: BRASILÂNDIA DO SUL | B5: 1 | C5: PREFEITO | D5: =VLOOKUP(Municipios!A5,CI!A$2:R$400,18,FALSE) -> 0 | E5: =B5-D5 -> 1 | F5: =VLOOKUP(Municipios!A5,CI!A$2:R$400,9,FALSE) -> 0.49958261 | G5: =VLOOKUP(A5,[1]CI!$A$2:$P$400,9,FALSE) -> 0.018461481 | H5: =VLOOKUP(A5,[1]CI!$A$2:$Q$400,17,FALSE) -> 168 | L5: Espigão Alto do Iguaçu | P5: 5
A6: CAFELÂNDIA | B6: 1 | C6: R | D6: =VLOOKUP(Municipios!A6,CI!A$2:R$400,18,FALSE) -> 0 | E6: =B6-D6 -> 1 | F6: =VLOOKUP(Municipios!A6,CI!A$2:R$400,9,FALSE) -> 0.31813388 | G6: =VLOOKUP(A6,[1]CI!$A$2:$P$400,9,FALSE) -> 0.10090967 | H6: =VLOOKUP(A6,[1]CI!$A$2:$Q$400,17,FALSE) -> 384 | L6: Laranjal | P6: 4
A7: CAMBARÁ | B7: 1 | C7: PREFEITO | D7: =VLOOKUP(Municipios!A7,CI!A$2:R$400,18,FALSE) -> 1 | E7: =B7-D7 -> 0 | F7: =VLOOKUP(Municipios!A7,CI!A$2:R$400,9,FALSE) -> 0.49498292 | G7: =VLOOKUP(A7,[1]CI!$A$2:$P$400,9,FALSE) -> 0.11167232 | H7: =VLOOKUP(A7,[1]CI!$A$2:$Q$400,17,FALSE) -> 164 | L7: General Carneiro | P7: 4
A8: CORUMBATAÍ DO SUL | B8: 1 | C8: SD | D8: =VLOOKUP(Municipios!A8,CI!A$2:R$400,18,FALSE) -> 0 | E8: =B8-D8 -> 1 | F8: =VLOOKUP(Municipios!A8,CI!A$2:R$400,9,FALSE) -> 0.50240487 | G8: =VLOOKUP(A8,[1]CI!$A$2:$P$400,9,FALSE) -> 0.018068683 | H8: =VLOOKUP(A8,[1]CI!$A$2:$Q$400,17,FALSE) -> 147 | L8: Cruzmaltina | P8: 4
A9: DOIS VIZINHOS | B9: 1 | C9: PREFEITO | D9: =VLOOKUP(Municipios!A9,CI!A$2:R$400,18,FALSE) -> 1 | E9: =B9-D9 -> 0 | F9: =VLOOKUP(Municipios!A9,CI!A$2:R$400,9,FALSE) -> 0.34756344 | G9: =VLOOKUP(A9,[1]CI!$A$2:$P$400,9,FALSE) -> 0.22711549 | H9: =VLOOKUP(A9,[1]CI!$A$2:$Q$400,17,FALSE) -> 363 | L9: Nova Laranjeiras | P9: 3
A10: DOUTOR CAMARGO | B10: 1 | C10: SD | D10: =VLOOKUP(Municipios!A10,CI!A$2:R$400,18,FALSE) -> 0 | E10: =B10-D10 -> 1 | F10: =VLOOKUP(Municipios!A10,CI!A$2:R$400,9,FALSE) -> 0.47901897 | G10: =VLOOKUP(A10,[1]CI!$A$2:$P$400,9,FALSE) -> 0.027063745 | H10: =VLOOKUP(A10,[1]CI!$A$2:$Q$400,17,FALSE) -> 195 | L10: Rio Branco do Ivaí | P10: 3
A11: ENÉAS MARQUES | B11: 1 | C11: YAN | D11: =VLOOKUP(Municipios!A11,CI!A$2:R$400,18,FALSE) -> 0 | E11: =B11-D11 -> 1 | F11: =VLOOKUP(Municipios!A11,CI!A$2:R$400,9,FALSE) -> 0.48542394 | G11: =VLOOKUP(A11,[1]CI!$A$2:$P$400,9,FALSE) -> 0.030716761 | H11: =VLOOKUP(A11,[1]CI!$A$2:$Q$400,17,FALSE) -> 182 | L11: Antônio Olinto | P11: 3
A12: FAXINAL | B12: 1 | C12: SD | D12: =VLOOKUP(Municipios!A12,CI!A$2:R$400,18,FALSE) -> 1 | E12: =B12-D12 -> 0 | F12: =VLOOKUP(Municipios!A12,CI!A$2:R$400,9,FALSE) -> 0.53801157 | G12: =VLOOKUP(A12,[1]CI!$A$2:$P$400,9,FALSE) -> 0.092268123 | H12: =VLOOKUP(A12,[1]CI!$A$2:$Q$400,17,FALSE) -> 101 | L12: Guamiranga | P12: 2
A13: FLORESTA | B13: 1 | C13: SD | D13: =VLOOKUP(Municipios!A13,CI!A$2:R$400,18,FALSE) -> 0 | E13: =B13-D13 -> 1 | F13: =VLOOKUP(Municipios!A13,CI!A$2:R$400,9,FALSE) -> 0.36036156 | G13: =VLOOKUP(A13,[1]CI!$A$2:$P$400,9,FALSE) -> 0.057819786 | H13: =VLOOKUP(A13,[1]CI!$A$2:$Q$400,17,FALSE) -> 353 | L13: Coronel Domingos Soares | P13: 2
A14: GOIOERÊ | B14: 1 | C14: PREFEITO | D14: =VLOOKUP(Municipios!A14,CI!A$2:R$400,18,FALSE) -> 1 | E14: =B14-D14 -> 0 | F14: =VLOOKUP(Municipios!A14,CI!A$2:R$400,9,FALSE) -> 0.41353574 | G14: =VLOOKUP(A14,[1]CI!$A$2:$P$400,9,FALSE) -> 0.13912886 | H14: =VLOOKUP(A14,[1]CI!$A$2:$Q$400,17,FALSE) -> 286 | L14: Rio Bonito do Iguaçu | P14: 2
A15: ITAGUAJÉ | B15: 1 | C15: SD | D15: =VLOOKUP(Municipios!A15,CI!A$2:R$400,18,FALSE) -> 0 | E15: =B15-D15 -> 1 | F15: =VLOOKUP(Municipios!A15,CI!A$2:R$400,9,FALSE) -> 0.40792 | G15: =VLOOKUP(A15,[1]CI!$A$2:$P$400,9,FALSE) -> 0.024824799 | H15: =VLOOKUP(A15,[1]CI!$A$2:$Q$400,17,FALSE) -> 300 | L15: Inácio Martins | P15: 2
... A19: LUPIONÓPOLIS | B19: 1 | C19: SD | D19: =VLOOKUP(Municipios!A19,CI!A$2:R$400,18,FALSE) -> 0 | E19: =B19-D19 -> 1 | F19: =VLOOKUP(Municipios!A19,CI!A$2:R$400,9,FALSE) -> 0.47871159 | G19: =VLOOKUP(A19,[1]CI!$A$2:$P$400,9,FALSE) -> 0.023764246 | H19: =VLOOKUP(A19,[1]CI!$A$2:$Q$400,17,FALSE) -> 198 | L19: Tunas do Paraná | P19: 2
A20: MANDAGUARI | B20: 1 | C20: SD | D20: =VLOOKUP(Municipios!A20,CI!A$2:R$400,18,FALSE) -> 1 | E20: =B20-D20 -> 0 | F20: =VLOOKUP(Municipios!A20,CI!A$2:R$400,9,FALSE) -> 0.34000139 | G20: =VLOOKUP(A20,[1]CI!$A$2:$P$400,9,FALSE) -> 0.17585542 | H20: =VLOOKUP(A20,[1]CI!$A$2:$Q$400,17,FALSE) -> 369 | L20: São José da Boa Vista
A21: MARIALVA | B21: 1 | C21: SD | D21: =VLOOKUP(Municipios!A21,CI!A$2:R$400,18,FALSE) -> 1 | E21: =B21-D21 -> 0 | F21: =VLOOKUP(Municipios!A21,CI!A$2:R$400,9,FALSE) -> 0.42105803 | G21: =VLOOKUP(A21,[1]CI!$A$2:$P$400,9,FALSE) -> 0.2139175 | H21: =VLOOKUP(A21,[1]CI!$A$2:$Q$400,17,FALSE) -> 290 | L21: Francisco Alves
A22: MARIPÁ | B22: 1 | C22: SD | D22: =VLOOKUP(Municipios!A22,CI!A$2:R$400,18,FALSE) -> 0 | E22: =B22-D22 -> 1 | F22: =VLOOKUP(Municipios!A22,CI!A$2:R$400,9,FALSE) -> 0.38098613 | G22: =VLOOKUP(A22,[1]CI!$A$2:$P$400,9,FALSE) -> 0.037983514 | H22: =VLOOKUP(A22,[1]CI!$A$2:$Q$400,17,FALSE) -> 337 | L22: Campina do Simão
A23: MARQUINHO | B23: 1 | C23: PREFEITO | D23: =VLOOKUP(Municipios!A23,CI!A$2:R$400,18,FALSE) -> 0 | E23: =B23-D23 -> 1 | F23: =VLOOKUP(Municipios!A23,CI!A$2:R$400,9,FALSE) -> 0.52211437 | G23: =VLOOKUP(A23,[1]CI!$A$2:$P$400,9,FALSE) -> 0.025492555 | H23: =VLOOKUP(A23,[1]CI!$A$2:$Q$400,17,FALSE) -> 121 | L23: Almirante Tamandaré
A24: NOSSA SENHORA DAS GRAÇAS | B24: 1 | C24: SD | D24: =VLOOKUP(Municipios!A24,CI!A$2:R$400,18,FALSE) -> 0 | E24: =B24-D24 -> 1 | F24: =VLOOKUP(Municipios!A24,CI!A$2:R$400,9,FALSE) -> 0.50415254 | G24: =VLOOKUP(A24,[1]CI!$A$2:$P$400,9,FALSE) -> 0.01854004 | H24: =VLOOKUP(A24,[1]CI!$A$2:$Q$400,17,FALSE) -> 154 | L24: Ribeirão do Pinhal
A25: NOVA LONDRINA | B25: 1 | C25: PREFEITO | D25: =VLOOKUP(Municipios!A25,CI!A$2:R$400,18,FALSE) -> 0 | E25: =B25-D25 -> 1 | F25: =VLOOKUP(Municipios!A25,CI!A$2:R$400,9,FALSE) -> 0.36708596 | G25: =VLOOKUP(A25,[1]CI!$A$2:$P$400,9,FALSE) -> 0.066618449 | H25: =VLOOKUP(A25,[1]CI!$A$2:$Q$400,17,FALSE) -> 344 | L25: Cândido de Abreu
A26: PAIÇANDU | B26: 1 | C26: SD | D26: =VLOOKUP(Municipios!A26,CI!A$2:R$400,18,FALSE) -> 1 | E26: =B26-D26 -> 0 | F26: =VLOOKUP(Municipios!A26,CI!A$2:R$400,9,FALSE) -> 0.47591304 | G26: =VLOOKUP(A26,[1]CI!$A$2:$P$400,9,FALSE) -> 0.25025126 | H26: =VLOOKUP(A26,[1]CI!$A$2:$Q$400,17,FALSE) -> 205 | L26: Mato Rico
A27: PLANALTO | B27: 1 | C27: PREFEITO | D27: =VLOOKUP(Municipios!A27,CI!A$2:R$400,18,FALSE) -> 0 | E27: =B27-D27 -> 1 | F27: =VLOOKUP(Municipios!A27,CI!A$2:R$400,9,FALSE) -> 0.44019514 | G27: =VLOOKUP(A27,[1]CI!$A$2:$P$400,9,FALSE) -> 0.061669201 | H27: =VLOOKUP(A27,[1]CI!$A$2:$Q$400,17,FALSE) -> 249 | L27: Japira
A28: PONTA GROSSA | B28: 1 | C28: R | D28: =VLOOKUP(Municipios!A28,CI!A$2:R$400,18,FALSE) -> 4 | E28: =B28-D28 -> -3 | F28: =VLOOKUP(Municipios!A28,CI!A$2:R$400,9,FALSE) -> 0.47751966 | G28: =VLOOKUP(A28,[1]CI!$A$2:$P$400,9,FALSE) -> 1.9818203 | H28: =VLOOKUP(A28,[1]CI!$A$2:$Q$400,17,FALSE) -> 207 | L28: Campo do Tenente
A29: PORECATU | B29: 1 | C29: SD | D29: =VLOOKUP(Municipios!A29,CI!A$2:R$400,18,FALSE) -> 0 | E29: =B29-D29 -> 1 | F29: =VLOOKUP(Municipios!A29,CI!A$2:R$400,9,FALSE) -> 0.45782123 | G29: =VLOOKUP(A29,[1]CI!$A$2:$P$400,9,FALSE) -> 0.051535026 | H29: =VLOOKUP(A29,[1]CI!$A$2:$Q$400,17,FALSE) -> 216 | L29: Itaperuçu
A30: QUEDAS DO IGUAÇU | B30: 1 | C30: PREFEITO | D30: =VLOOKUP(Municipios!A30,CI!A$2:R$400,18,FALSE) -> 1 | E30: =B30-D30 -> 0 | F30: =VLOOKUP(Municipios!A30,CI!A$2:R$400,9,FALSE) -> 0.61563135 | G30: =VLOOKUP(A30,[1]CI!$A$2:$P$400,9,FALSE) -> 0.17306656 | H30: =VLOOKUP(A30,[1]CI!$A$2:$Q$400,17,FALSE) -> 45 | L30: Goioxim
A31: QUINTA DO SOL | B31: 1 | C31: SD | D31: =VLOOKUP(Municipios!A31,CI!A$2:R$400,18,FALSE) -> 0 | E31: =B31-D31 -> 1 | F31: =VLOOKUP(Municipios!A31,CI!A$2:R$400,9,FALSE) -> 0.52394252 | G31: =VLOOKUP(A31,[1]CI!$A$2:$P$400,9,FALSE) -> 0.025139037 | H31: =VLOOKUP(A31,[1]CI!$A$2:$Q$400,17,FALSE) -> 126 | L31: Mariluz
... A35: SARANDI | B35: 1 | C35: SD | D35: =VLOOKUP(Municipios!A35,CI!A$2:R$400,18,FALSE) -> 2 | E35: =B35-D35 -> -1 | F35: =VLOOKUP(Municipios!A35,CI!A$2:R$400,9,FALSE) -> 0.51489008 | G35: =VLOOKUP(A35,[1]CI!$A$2:$P$400,9,FALSE) -> 0.66370986 | H35: =VLOOKUP(A35,[1]CI!$A$2:$Q$400,17,FALSE) -> 150 | L35: Bocaiúva do Sul
L36: Santa Maria do Oeste
L37: Rio Azul
L38: Grandes Rios
L39: Teixeira Soares
L40: Agudos do Sul
L41: São Jerônimo da Serra
L42: Honório Serpa
L43: Reserva
L44: Luiziana
L45: Quedas do Iguaçu
L46: Palmital
...
